Workbook

Sheet Ciudad tablero
A1: CIUDAD REGULADA MAESTRO | B1: NOMORIGEN | C1: ORIGEN
A2: SANTA ROSA DEL SUR BOLIVAR | B2: SANTA ROSA DEL SUR BOLIVAR | C2: 13688000
A3: CIMITARRA SANTANDER | B3: CIMITARRA SANTANDER | C3: 68190000
B4: ABREGO NORTE DE SANTANDER | C4: 54003000
A5: ACACIAS META | B5: ACACIAS META | C5: 50006000
B6: ADJUNTAS AGUACHICA CESAR | C6: 20011016
A7: PARAGUACHON MAICAO LA GUAJIRA | B7: PARAGUACHON MAICAO LA GUAJIRA | C7: 44430007
A8: AEROPUERTO RIONEGRO ANTIOQUIA | B8: AEROPUERTO RIONEGRO ANTIOQUIA | C8: 5615010
B9: AGUA DE DIOS CUNDINAMARCA | C9: 25001000
A10: AGUACHICA CESAR | B10: AGUACHICA CESAR | C10: 20011000
B11: AGUADAS CALDAS | C11: 17013000
A12: ARROYOHONDO YUMBO VALLE DEL CAUCA | B12: ARROYOHONDO YUMBO VALLE DEL CAUCA | C12: 76892017
B13: AGUAZUL CASANARE | C13: 85010000
A14: AGUSTIN CODAZZI | B14: AGUSTIN CODAZZI CESAR | C14: 20013000
B15: AIPE HUILA | C15: 41016000
B16: ALBAN CUNDINAMARCA | C16: 25019000
A17: ALBANIA | B17: ALBANIA LA GUAJIRA | C17: 44035000
B18: ALCALA VALLE DEL CAUCA | C18: 76020000
B19: ALVARADO TOLIMA | C19: 73026000
A20: AMAGA ANTIOQUIA | B20: AMAGA ANTIOQUIA | C20: 5030000
B21: AMALFI ANTIOQUIA | C21: 5031000
B22: ANAPOIMA CUNDINAMARCA | C22: 25035000
B23: ANDALUCIA VALLE DEL CAUCA | C23: 76036000
B24: ANDES ANTIOQUIA | C24: 5034000
B25: ANOLAIMA CUNDINAMARCA | C25: 25040000
A26: ANSERMANUEVO VALLE DEL CAUCA | B26: ANSERMANUEVO VALLE DEL CAUCA | C26: 76041000
B27: ANTONIA SANTOS TOCANCIPA CUNDINAMARCA | C27: 25817014
A28: APARTADO ANTIOQUIA | B28: APARTADO ANTIOQUIA | C28: 5045000
B29: APIAY VILLAVICENCIO META | C29: 50001019
A30: ARACATACA MAGDALENA | B30: ARACATACA MAGDALENA | C30: 47053000
B31: ARATOCA SANTANDER | C31: 68051000
A32: ARAUCA ARAUCA | B32: ARAUCA ARAUCA | C32: 81001000
A33: NUEVA COLONIA TURBO ANTIOQUIA | B33: NUEVA COLONIA TURBO ANTIOQUIA | C33: 5837002
B34: ARAUCA PALESTINA CALDAS | C34: 17524001
B35: ARAUQUITA ARAUCA | C35: 81065000
B36: ARBELAEZ CUNDINAMARCA | C36: 25053000
B37: ARBOLETES ANTIOQUIA | C37: 5051000
B38: ARCABUCO BOYACA | C38: 15051000
B39: ARGELIA CAUCA | C39: 19050000
B40: ARIGUANI MAGDALENA | C40: 47058000
...

Sheet Calculo viajes maximos
B1: viaje smaximos al mes
A2: 0 | B2: 25 | C2: -
A3: 250 | B3: 25 | C3: 6250
A4: 251 | B4: 16 | C4: 4016 | D4: 1.5
A5: 500 | B5: 16 | C5: 8000 | D5: =25/B5 -> 1.5625
A6: 501 | B6: 12 | C6: 6012 | D6: 2
A7: 800 | B7: 12 | C7: 9600 | D7: =25/B7 -> 2.0833333
A8: 801 | B8: 8 | C8: 6408 | D8: 3
A9: 1100 | B9: 8 | C9: 8800 | D9: =25/B9 -> 3.125
A10: 1101 | B10: 6 | C10: 6606 | D10: 4
A11: 1400 | B11: 6 | C11: 8400 | D11: =25/B11 -> 4.1666667
A12: 1401 | B12: 5 | C12: 7005 | D12: =25/B12 -> 5
A13: 1700 | B13: 5 | C13: 8500 | D13: =25/B13 -> 5

Sheet Hoja3

Sheet Maestro de rutas depurado
A1: Origen | B1: Regional origen | C1: Ciudad origen | D1: Codigo origen | E1: Destino | F1: Regional destino | G1: Ciudad destino | H1: Codigo destino | I1: Llave simple | J1: Horas viaje | K1: Kilometros | L1: Operación | M1: Ruta | N1: Estado | O1: viajes maximos | P1: Verificacion
A2: ACACÍAS | B2: =IFERROR(VLOOKUP(A2,hoja!$A$2:$E$970,4,FALSE),0) -> CENTRO | C2: =IFERROR(VLOOKUP(A2,hoja!$A$2:$E$1370,5,FALSE),0) -> ACACÍAS | D2: =IFERROR(VLOOKUP(A2,hoja!A:D,3,FALSE),0) -> 60004 | E2: NUTRIMENTI COPACABANA | F2: =IFERROR(VLOOKUP(E2,hoja!$A$2:$E$970,4,FALSE),0) -> ANTIOQUIA | G2: =IFERROR(VLOOKUP(E2,hoja!$A$2:$E$970,5,FALSE),0) -> MEDELLÍN | H2: =IFERROR(VLOOKUP(E2,hoja!A:C,3,FALSE),0) -> 50443 | I2: =D2&H2 -> 6000450443 | J2: 29.68 | K2: 542 | L2: =IF(B2=F2,"REGIONAL","NACIONAL") -> NACIONAL | M2: Principal | N2: {=IFERROR(IF(M2="Principal","LES_ACTIVE",LES_INACTIVE),0)} -> LES_ACTIVE | O2: =IF(K2<=250,25,IF(K2<=500,16,IF(K2<=800,12,IF(K2<=1100,8,IF(K2<=1400,6,IF(K2<=1700,5)))))) -> 12 | P2: =D2&H2&M2 -> 6000450443Principal
A3: AIRGAS MEDELLIN | B3: =IFERROR(VLOOKUP(A3,hoja!$A$2:$E$970,4,FALSE),0) -> ANTIOQUIA | C3: =IFERROR(VLOOKUP(A3,hoja!$A$2:$E$1370,5,FALSE),0) -> MEDELLÍN | D3: =IFERROR(VLOOKUP(A3,hoja!A:D,3,FALSE),0) -> 60100 | E3: DF TOCANCIPA AIR LIQUIDE | F3: =IFERROR(VLOOKUP(E3,hoja!$A$2:$E$970,4,FALSE),0) -> CENTRO | G3: =IFERROR(VLOOKUP(E3,hoja!$A$2:$E$970,5,FALSE),0) -> SESQUILÉ | H3: =IFERROR(VLOOKUP(E3,hoja!A:C,3,FALSE),0) -> 50193 | I3: =D3&H3 -> 6010050193 | K3: 448 | L3: =IF(B3=F3,"REGIONAL","NACIONAL") -> NACIONAL | M3: La vega | N3: LES_INACTIVE | O3: =IF(K3<=250,25,IF(K3<=500,16,IF(K3<=800,12,IF(K3<=1100,8,IF(K3<=1400,6,IF(K3<=1700,5)))))) -> 16 | P3: =D3&H3&M3 -> 6010050193La vega
A4: AIRGAS MEDELLIN | B4: =IFERROR(VLOOKUP(A4,hoja!$A$2:$E$970,4,FALSE),0) -> ANTIOQUIA | C4: =IFERROR(VLOOKUP(A4,hoja!$A$2:$E$1370,5,FALSE),0) -> MEDELLÍN | D4: =IFERROR(VLOOKUP(A4,hoja!A:D,3,FALSE),0) -> 60100 | E4: DF TOCANCIPA AIR LIQUIDE | F4: =IFERROR(VLOOKUP(E4,hoja!$A$2:$E$970,4,FALSE),0) -> CENTRO | G4: =IFERROR(VLOOKUP(E4,hoja!$A$2:$E$970,5,FALSE),0) -> SESQUILÉ | H4: =IFERROR(VLOOKUP(E4,hoja!A:C,3,FALSE),0) -> 50193 | I4: =D4&H4 -> 6010050193 | K4: 450 | L4: =IF(B4=F4,"REGIONAL","NACIONAL") -> NACIONAL | M4: Facatativa | N4: LES_ACTIVE | O4: =IF(K4<=250,25,IF(K4<=500,16,IF(K4<=800,12,IF(K4<=1100,8,IF(K4<=1400,6,IF(K4<=1700,5)))))) -> 16 | P4: =D4&H4&M4 -> 6010050193Facatativa
A5: AIR LIQUIDE SIBATE | B5: =IFERROR(VLOOKUP(A5,hoja!$A$2:$E$970,4,FALSE),0) -> CENTRO | C5: =IFERROR(VLOOKUP(A5,hoja!$A$2:$E$1370,5,FALSE),0) -> BOGOTÁ | D5: =IFERROR(VLOOKUP(A5,hoja!A:D,3,FALSE),0) -> 8101 | E5: AIR GAS | F5: =IFERROR(VLOOKUP(E5,hoja!$A$2:$E$970,4,FALSE),0) -> 0 | G5: =IFERROR(VLOOKUP(E5,hoja!$A$2:$E$970,5,FALSE),0) -> 0 | H5: =IFERROR(VLOOKUP(E5,hoja!A:C,3,FALSE),0) -> 0 | I5: =D5&H5 -> 81010 | J5: 20.450571 | K5: 435.77 | L5: =IF(B5=F5,"REGIONAL","NACIONAL") -> NACIONAL | M5: La vega | N5: LES_ACTIVE | O5: =IF(K5<=250,25,IF(K5<=500,16,IF(K5<=800,12,IF(K5<=1100,8,IF(K5<=1400,6,IF(K5<=1700,5)))))) -> 16 | P5: =D5&H5&M5 -> 81010La vega
A6: AIR LIQUIDE SIBATE | B6: =IFERROR(VLOOKUP(A6,hoja!$A$2:$E$970,4,FALSE),0) -> CENTRO | C6: =IFERROR(VLOOKUP(A6,hoja!$A$2:$E$1370,5,FALSE),0) -> BOGOTÁ | D6: =IFERROR(VLOOKUP(A6,hoja!A:D,3,FALSE),0) -> 8101 | E6: AIRGAS MEDELLIN | F6: =IFERROR(VLOOKUP(E6,hoja!$A$2:$E$970,4,FALSE),0) -> ANTIOQUIA | G6: =IFERROR(VLOOKUP(E6,hoja!$A$2:$E$970,5,FALSE),0) -> MEDELLÍN | H6: =IFERROR(VLOOKUP(E6,hoja!A:C,3,FALSE),0) -> 60100 | I6: =D6&H6 -> 810160100 | J6: 39 | K6: 435.766 | L6: =IF(B6=F6,"REGIONAL","NACIONAL") -> NACIONAL | M6: Principal | N6: {=IFERROR(IF(M6="Principal","LES_ACTIVE",LES_INACTIVE),0)} -> LES_ACTIVE | O6: =IF(K6<=250,25,IF(K6<=500,16,IF(K6<=800,12,IF(K6<=1100,8,IF(K6<=1400,6,IF(K6<=1700,5)))))) -> 16 | P6: =D6&H6&M6 -> 810160100Principal
A7: AIR LIQUIDE SIBATE | B7: =IFERROR(VLOOKUP(A7,hoja!$A$2:$E$970,4,FALSE),0) -> CENTRO | C7: =IFERROR(VLOOKUP(A7,hoja!$A$2:$E$1370,5,FALSE),0) -> BOGOTÁ | D7: =IFERROR(VLOOKUP(A7,hoja!A:D,3,FALSE),0) -> 8101 | E7: ALQUERIA | F7: =IFERROR(VLOOKUP(E7,hoja!$A$2:$E$970,4,FALSE),0) -> 0 | G7: =IFERROR(VLOOKUP(E7,hoja!$A$2:$E$970,5,FALSE),0) -> 0 | H7: =IFERROR(VLOOKUP(E7,hoja!A:C,3,FALSE),0) -> 0 | I7: =D7&H7 -> 81010 | K7: 16.5 | L7: =IF(B7=F7,"REGIONAL","NACIONAL") -> NACIONAL | M7: Principal | N7: {=IFERROR(IF(M7="Principal","LES_ACTIVE",LES_INACTIVE),0)} -> LES_ACTIVE | O7: =IF(K7<=250,25,IF(K7<=500,16,IF(K7<=800,12,IF(K7<=1100,8,IF(K7<=1400,6,IF(K7<=1700,5)))))) -> 25 | P7: =D7&H7&M7 -> 81010Principal
A8: AIR LIQUIDE SIBATE | B8: =IFERROR(VLOOKUP(A8,hoja!$A$2:$E$970,4,FALSE),0) -> CENTRO | C8: =IFERROR(VLOOKUP(A8,hoja!$A$2:$E$1370,5,FALSE),0) -> BOGOTÁ | D8: =IFERROR(VLOOKUP(A8,hoja!A:D,3,FALSE),0) -> 8101 | E8: CEDI SANTAFE DE ANTIOQUIA | F8: =IFERROR(VLOOKUP(E8,hoja!$A$2:$E$970,4,FALSE),0) -> ANTIOQUIA | G8: =IFERROR(VLOOKUP(E8,hoja!$A$2:$E$970,5,FALSE),0) -> SANTA FE DE ANTIOQUIA | H8: =IFERROR(VLOOKUP(E8,hoja!A:C,3,FALSE),0) -> 0080 | I8: =D8&H8 -> 81010080 | J8: 24.085714 | K8: 563 | L8: =IF(B8=F8,"REGIONAL","NACIONAL") -> NACIONAL | M8: Principal | N8: {=IFERROR(IF(M8="Principal","LES_ACTIVE",LES_INACTIVE),0)} -> LES_ACTIVE | O8: =IF(K8<=250,25,IF(K8<=500,16,IF(K8<=800,12,IF(K8<=1100,8,IF(K8<=1400,6,IF(K8<=1700,5)))))) -> 12 | P8: =D8&H8&M8 -> 81010080Principal
A9: AIR LIQUIDE SIBATE | B9: =IFERROR(VLOOKUP(A9,hoja!$A$2:$E$970,4,FALSE),0) -> CENTRO | C9: =IFERROR(VLOOKUP(A9,hoja!$A$2:$E$1370,5,FALSE),0) -> BOGOTÁ | D9: =IFERROR(VLOOKUP(A9,hoja!A:D,3,FALSE),0) -> 8101 | E9: CEDI ZIPAQUIRA | F9: =IFERROR(VLOOKUP(E9,hoja!$A$2:$E$970,4,FALSE),0) -> CENTRO | G9: =IFERROR(VLOOKUP(E9,hoja!$A$2:$E$970,5,FALSE),0) -> ZIPAQUIRÁ | H9: =IFERROR(VLOOKUP(E9,hoja!A:C,3,FALSE),0) -> 0032 | I9: =D9&H9 -> 81010032 | J9: 0.40571429 | K9: 14.2 | L9: =IF(B9=F9,"REGIONAL","NACIONAL") -> REGIONAL | M9: Principal | N9: {=IFERROR(IF(M9="Principal","LES_ACTIVE",LES_INACTIVE),0)} -> LES_ACTIVE | O9: =IF(K9<=250,25,IF(K9<=500,16,IF(K9<=800,12,IF(K9<=1100,8,IF(K9<=1400,6,IF(K9<=1700,5)))))) -> 25 | P9: =D9&H9&M9 -> 81010032Principal
A10: AIR LIQUIDE SIBATE | B10: =IFERROR(VLOOKUP(A10,hoja!$A$2:$E$970,4,FALSE),0) -> CENTRO | C10: =IFERROR(VLOOKUP(A10,hoja!$A$2:$E$1370,5,FALSE),0) -> BOGOTÁ | D10: =IFERROR(VLOOKUP(A10,hoja!A:D,3,FALSE),0) -> 8101 | E10: CENTRAL CERVECERA - SESQUILE | F10: =IFERROR(VLOOKUP(E10,hoja!$A$2:$E$970,4,FALSE),0) -> CENTRO | G10: =IFERROR(VLOOKUP(E10,hoja!$A$2:$E$970,5,FALSE),0) -> SESQUILÉ | H10: =IFERROR(VLOOKUP(E10,hoja!A:C,3,FALSE),0) -> 1501 | I10: =D10&H10 -> 81011501 | J10: 2 | K10: 82.9385 | L10: =IF(B10=F10,"REGIONAL","NACIONAL") -> REGIONAL | M10: Principal | N10: {=IFERROR(IF(M10="Principal","LES_ACTIVE",LES_INACTIVE),0)} -> LES_ACTIVE | O10: =IF(K10<=250,25,IF(K10<=500,16,IF(K10<=800,12,IF(K10<=1100,8,IF(K10<=1400,6,IF(K10<=1700,5)))))) -> 25 | P10: =D10&H10&M10 -> 81011501Principal
A11: AIR LIQUIDE SIBATE | B11: =IFERROR(VLOOKUP(A11,hoja!$A$2:$E$970,4,FALSE),0) -> CENTRO | C11: =IFERROR(VLOOKUP(A11,hoja!$A$2:$E$1370,5,FALSE),0) -> BOGOTÁ | D11: =IFERROR(VLOOKUP(A11,hoja!A:D,3,FALSE),0) -> 8101 | E11: ENKA DE COLOMBIA | F11: =IFERROR(VLOOKUP(E11,hoja!$A$2:$E$970,4,FALSE),0) -> ANTIOQUIA | G11: =IFERROR(VLOOKUP(E11,hoja!$A$2:$E$970,5,FALSE),0) -> MEDELLÍN | H11: =IFERROR(VLOOKUP(E11,hoja!A:C,3,FALSE),0) -> 3038 | I11: =D11&H11 -> 81013038 | J11: 20.684857 | K11: 463 | L11: =IF(B11=F11,"REGIONAL","NACIONAL") -> NACIONAL | M11: Principal | N11: LES_ACTIVE | O11: =IF(K11<=250,25,IF(K11<=500,16,IF(K11<=800,12,IF(K11<=1100,8,IF(K11<=1400,6,IF(K11<=1700,5)))))) -> 16 | P11: =D11&H11&M11 -> 81013038Principal
A12: AIR LIQUIDE SIBATE | B12: =IFERROR(VLOOKUP(A12,hoja!$A$2:$E$970,4,FALSE),0) -> CENTRO | C12: =IFERROR(VLOOKUP(A12,hoja!$A$2:$E$1370,5,FALSE),0) -> BOGOTÁ | D12: =IFERROR(VLOOKUP(A12,hoja!A:D,3,FALSE),0) -> 8101 | E12: ENKA DE COLOMBIA | F12: =IFERROR(VLOOKUP(E12,hoja!$A$2:$E$970,4,FALSE),0) -> ANTIOQUIA | G12: =IFERROR(VLOOKUP(E12,hoja!$A$2:$E$970,5,FALSE),0) -> MEDELLÍN | H12: =IFERROR(VLOOKUP(E12,hoja!A:C,3,FALSE),0) -> 3038 | I12: =D12&H12 -> 81013038 | J12: 20.684857 | K12: 443.97 | L12: =IF(B12=F12,"REGIONAL","NACIONAL") -> NACIONAL | M12: La vega | N12: LES_INACTIVE | O12: =IF(K12<=250,25,IF(K12<=500,16,IF(K12<=800,12,IF(K12<=1100,8,IF(K12<=1400,6,IF(K12<=1700,5)))))) -> 16 | P12: =D12&H12&M12 -> 81013038La vega
A13: AIR LIQUIDE SIBATE | B13: =IFERROR(VLOOKUP(A13,hoja!$A$2:$E$970,4,FALSE),0) -> CENTRO | C13: =IFERROR(VLOOKUP(A13,hoja!$A$2:$E$1370,5,FALSE),0) -> BOGOTÁ | D13: =IFERROR(VLOOKUP(A13,hoja!A:D,3,FALSE),0) -> 8101 | E13: ENKA DE COLOMBIA | F13: =IFERROR(VLOOKUP(E13,hoja!$A$2:$E$970,4,FALSE),0) -> ANTIOQUIA | G13: =IFERROR(VLOOKUP(E13,hoja!$A$2:$E$970,5,FALSE),0) -> MEDELLÍN | H13: =IFERROR(VLOOKUP(E13,hoja!A:C,3,FALSE),0) -> 3038 | I13: =D13&H13 -> 81013038 | J13: 20.684857 | K13: 448 | L13: =IF(B13=F13,"REGIONAL","NACIONAL") -> NACIONAL | M13: Chía | N13: LES_INACTIVE | O13: =IF(K13<=250,25,IF(K13<=500,16,IF(K13<=800,12,IF(K13<=1100,8,IF(K13<=1400,6,IF(K13<=1700,5)))))) -> 16 | P13: =D13&H13&M13 -> 81013038Chía
A14: AIR LIQUIDE SIBATE | B14: =IFERROR(VLOOKUP(A14,hoja!$A$2:$E$970,4,FALSE),0) -> CENTRO | C14: =IFERROR(VLOOKUP(A14,hoja!$A$2:$E$1370,5,FALSE),0) -> BOGOTÁ | D14: =IFERROR(VLOOKUP(A14,hoja!A:D,3,FALSE),0) -> 8101 | E14: GASCOL CENTRO | F14: =IFERROR(VLOOKUP(E14,hoja!$A$2:$E$970,4,FALSE),0) -> CENTRO | G14: =IFERROR(VLOOKUP(E14,hoja!$A$2:$E$970,5,FALSE),0) -> BOGOTÁ | H14: =IFERROR(VLOOKUP(E14,hoja!A:C,3,FALSE),0) -> 0002 | I14: =D14&H14 -> 81010002 | J14: 2.4833333 | K14: 63 | L14: =IF(B14=F14,"REGIONAL","NACIONAL") -> REGIONAL | M14: Principal | N14: {=IFERROR(IF(M14="Principal","LES_ACTIVE",LES_INACTIVE),0)} -> LES_ACTIVE | O14: =IF(K14<=250,25,IF(K14<=500,16,IF(K14<=800,12,IF(K14<=1100,8,IF(K14<=1400,6,IF(K14<=1700,5)))))) -> 25 | P14: =D14&H14&M14 -> 81010002Principal
A15: AIR LIQUIDE SIBATE | B15: =IFERROR(VLOOKUP(A15,hoja!$A$2:$E$970,4,FALSE),0) -> CENTRO | C15: =IFERROR(VLOOKUP(A15,hoja!$A$2:$E$1370,5,FALSE),0) -> BOGOTÁ | D15: =IFERROR(VLOOKUP(A15,hoja!A:D,3,FALSE),0) -> 8101 | E15: GASCOL SUR | F15: =IFERROR(VLOOKUP(E15,hoja!$A$2:$E$970,4,FALSE),0) -> CENTRO | G15: =IFERROR(VLOOKUP(E15,hoja!$A$2:$E$970,5,FALSE),0) -> BOGOTÁ | H15: =IFERROR(VLOOKUP(E15,hoja!A:C,3,FALSE),0) -> 0011 | I15: =D15&H15 -> 81010011 | J15: 6 | K15: 63 | L15: =IF(B15=F15,"REGIONAL","NACIONAL") -> REGIONAL | M15: Principal | N15: {=IFERROR(IF(M15="Principal","LES_ACTIVE",LES_INACTIVE),0)} -> LES_ACTIVE | O15: =IF(K15<=250,25,IF(K15<=500,16,IF(K15<=800,12,IF(K15<=1100,8,IF(K15<=1400,6,IF(K15<=1700,5)))))) -> 25 | P15: =D15&H15&M15 -> 81010011Principal
A16: AIR LIQUIDE SIBATE | B16: =IFERROR(VLOOKUP(A16,hoja!$A$2:$E$970,4,FALSE),0) -> CENTRO | C16: =IFERROR(VLOOKUP(A16,hoja!$A$2:$E$1370,5,FALSE),0) -> BOGOTÁ | D16: =IFERROR(VLOOKUP(A16,hoja!A:D,3,FALSE),0) -> 8101 | E16: GASEOSAS LUX BOGOTA | F16: =IFERROR(VLOOKUP(E16,hoja!$A$2:$E$970,4,FALSE),0) -> CENTRO | G16: =IFERROR(VLOOKUP(E16,hoja!$A$2:$E$970,5,FALSE),0) -> BOGOTÁ | H16: =IFERROR(VLOOKUP(E16,hoja!A:C,3,FALSE),0) -> 0021 | I16: =D16&H16 -> 81010021 | J16: 3.2 | K16: 112 | L16: =IF(B16=F16,"REGIONAL","NACIONAL") -> REGIONAL | M16: Principal | N16: {=IFERROR(IF(M16="Principal","LES_ACTIVE",LES_INACTIVE),0)} -> LES_ACTIVE | O16: =IF(K16<=250,25,IF(K16<=500,16,IF(K16<=800,12,IF(K16<=1100,8,IF(K16<=1400,6,IF(K16<=1700,5)))))) -> 25 | P16: =D16&H16&M16 -> 81010021Principal
A17: AIR LIQUIDE SIBATE | B17: =IFERROR(VLOOKUP(A17,hoja!$A$2:$E$970,4,FALSE),0) -> CENTRO | C17: =IFERROR(VLOOKUP(A17,hoja!$A$2:$E$1370,5,FALSE),0) -> BOGOTÁ | D17: =IFERROR(VLOOKUP(A17,hoja!A:D,3,FALSE),0) -> 8101 | E17: GASEOSAS LUX DUITAMA | F17: =IFERROR(VLOOKUP(E17,hoja!$A$2:$E$970,4,FALSE),0) -> CENTRO | G17: =IFERROR(VLOOKUP(E17,hoja!$A$2:$E$970,5,FALSE),0) -> DUITAMA | H17: =IFERROR(VLOOKUP(E17,hoja!A:C,3,FALSE),0) -> 0441 | I17: =D17&H17 -> 81010441 | J17: 11.153333 | K17: 237.6655 | L17: =IF(B17=F17,"REGIONAL","NACIONAL") -> REGIONAL | M17: Principal | N17: {=IFERROR(IF(M17="Principal","LES_ACTIVE",LES_INACTIVE),0)} -> LES_ACTIVE | O17: =IF(K17<=250,25,IF(K17<=500,16,IF(K17<=800,12,IF(K17<=1100,8,IF(K17<=1400,6,IF(K17<=1700,5)))))) -> 25 | P17: =D17&H17&M17 -> 81010441Principal
A18: AIR LIQUIDE SIBATE | B18: =IFERROR(VLOOKUP(A18,hoja!$A$2:$E$970,4,FALSE),0) -> CENTRO | C18: =IFERROR(VLOOKUP(A18,hoja!$A$2:$E$1370,5,FALSE),0) -> BOGOTÁ | D18: =IFERROR(VLOOKUP(A18,hoja!A:D,3,FALSE),0) -> 8101 | E18: GASEOSAS LUX PIEDECUESTA | F18: =IFERROR(VLOOKUP(E18,hoja!$A$2:$E$970,4,FALSE),0) -> SANTANDER | G18: =IFERROR(VLOOKUP(E18,hoja!$A$2:$E$970,5,FALSE),0) -> PIEDECUESTA | H18: =IFERROR(VLOOKUP(E18,hoja!A:C,3,FALSE),0) -> 0422 | I18: =D18&H18 -> 81010422 | J18: 23 | K18: 430.588 | L18: =IF(B18=F18,"REGIONAL","NACIONAL") -> NACIONAL | M18: Principal | N18: {=IFERROR(IF(M18="Principal","LES_ACTIVE",LES_INACTIVE),0)} -> LES_ACTIVE | O18: =IF(K18<=250,25,IF(K18<=500,16,IF(K18<=800,12,IF(K18<=1100,8,IF(K18<=1400,6,IF(K18<=1700,5)))))) -> 16 | P18: =D18&H18&M18 -> 81010422Principal
A19: AIR LIQUIDE SIBATE | B19: =IFERROR(VLOOKUP(A19,hoja!$A$2:$E$970,4,FALSE),0) -> CENTRO | C19: =IFERROR(VLOOKUP(A19,hoja!$A$2:$E$1370,5,FALSE),0) -> BOGOTÁ | D19: =IFERROR(VLOOKUP(A19,hoja!A:D,3,FALSE),0) -> 8101 | E19: GASEOSAS GLACIAL MARIQUITA | F19: =IFERROR(VLOOKUP(E19,hoja!$A$2:$E$970,4,FALSE),0) -> CENTRO | G19: =IFERROR(VLOOKUP(E19,hoja!$A$2:$E$970,5,FALSE),0) -> MARIQUITA | H19: =IFERROR(VLOOKUP(E19,hoja!A:C,3,FALSE),0) -> 50170 | I19: =D19&H19 -> 810150170 | K19: 292 | L19: =IF(B19=F19,"REGIONAL","NACIONAL") -> REGIONAL | M19: Facatativa | N19: LES_ACTIVE | O19: =IF(K19<=250,25,IF(K19<=500,16,IF(K19<=800,12,IF(K19<=1100,8,IF(K19<=1400,6,IF(K19<=1700,5)))))) -> 16 | P19: =D19&H19&M19 -> 810150170Facatativa
A20: AIR LIQUIDE SIBATE | B20: =IFERROR(VLOOKUP(A20,hoja!$A$2:$E$970,4,FALSE),0) -> CENTRO | C20: =IFERROR(VLOOKUP(A20,hoja!$A$2:$E$1370,5,FALSE),0) -> BOGOTÁ | D20: =IFERROR(VLOOKUP(A20,hoja!A:D,3,FALSE),0) -> 8101 | E20: METAL | F20: =IFERROR(VLOOKUP(E20,hoja!$A$2:$E$970,4,FALSE),0) -> CENTRO | G20: =IFERROR(VLOOKUP(E20,hoja!$A$2:$E$970,5,FALSE),0) -> BOGOTÁ | H20: =IFERROR(VLOOKUP(E20,hoja!A:C,3,FALSE),0) -> 10229 | I20: =D20&H20 -> 810110229 | J20: 1.1942857 | K20: 41.8 | L20: =IF(B20=F20,"REGIONAL","NACIONAL") -> REGIONAL | M20: Principal | N20: {=IFERROR(IF(M20="Principal","LES_ACTIVE",LES_INACTIVE),0)} -> LES_ACTIVE | O20: =IF(K20<=250,25,IF(K20<=500,16,IF(K20<=800,12,IF(K20<=1100,8,IF(K20<=1400,6,IF(K20<=1700,5)))))) -> 25 | P20: =D20&H20&M20 -> 810110229Principal
A21: AIR LIQUIDE SIBATE | B21: =IFERROR(VLOOKUP(A21,hoja!$A$2:$E$970,4,FALSE),0) -> CENTRO | C21: =IFERROR(VLOOKUP(A21,hoja!$A$2:$E$1370,5,FALSE),0) -> BOGOTÁ | D21: =IFERROR(VLOOKUP(A21,hoja!A:D,3,FALSE),0) -> 8101 | E21: NUTRIMENTI COPACABANA | F21: =IFERROR(VLOOKUP(E21,hoja!$A$2:$E$970,4,FALSE),0) -> ANTIOQUIA | G21: =IFERROR(VLOOKUP(E21,hoja!$A$2:$E$970,5,FALSE),0) -> MEDELLÍN | H21: =IFERROR(VLOOKUP(E21,hoja!A:C,3,FALSE),0) -> 50443 | I21: =D21&H21 -> 810150443 | J21: 20.342857 | K21: 432 | L21: =IF(B21=F21,"REGIONAL","NACIONAL") -> NACIONAL | M21: Principal | N21: {=IFERROR(IF(M21="Principal","LES_ACTIVE",LES_INACTIVE),0)} -> LES_ACTIVE | O21: =IF(K21<=250,25,IF(K21<=500,16,IF(K21<=800,12,IF(K21<=1100,8,IF(K21<=1400,6,IF(K21<=1700,5)))))) -> 16 | P21: =D21&H21&M21 -> 810150443Principal
A22: AIR LIQUIDE SIBATE | B22: =IFERROR(VLOOKUP(A22,hoja!$A$2:$E$970,4,FALSE),0) -> CENTRO | C22: =IFERROR(VLOOKUP(A22,hoja!$A$2:$E$1370,5,FALSE),0) -> BOGOTÁ | D22: =IFERROR(VLOOKUP(A22,hoja!A:D,3,FALSE),0) -> 8101 | E22: OXIGENO | F22: =IFERROR(VLOOKUP(E22,hoja!$A$2:$E$970,4,FALSE),0) -> ANTIOQUIA | G22: =IFERROR(VLOOKUP(E22,hoja!$A$2:$E$970,5,FALSE),0) -> MEDELLÍN | H22: =IFERROR(VLOOKUP(E22,hoja!A:C,3,FALSE),0) -> 10227 | I22: =D22&H22 -> 810110227 | J22: 20.450571 | K22: 435.77 | L22: =IF(B22=F22,"REGIONAL","NACIONAL") -> NACIONAL | M22: Principal | N22: {=IFERROR(IF(M22="Principal","LES_ACTIVE",LES_INACTIVE),0)} -> LES_ACTIVE | O22: =IF(K22<=250,25,IF(K22<=500,16,IF(K22<=800,12,IF(K22<=1100,8,IF(K22<=1400,6,IF(K22<=1700,5)))))) -> 16 | P22: =D22&H22&M22 -> 810110227Principal
A23: AIR LIQUIDE SIBATE | B23: =IFERROR(VLOOKUP(A23,hoja!$A$2:$E$970,4,FALSE),0) -> CENTRO | C23: =IFERROR(VLOOKUP(A23,hoja!$A$2:$E$1370,5,FALSE),0) -> BOGOTÁ | D23: =IFERROR(VLOOKUP(A23,hoja!A:D,3,FALSE),0) -> 8101 | E23: POSTOBON BELLO | F23: =IFERROR(VLOOKUP(E23,hoja!$A$2:$E$970,4,FALSE),0) -> ANTIOQUIA | G23: =IFERROR(VLOOKUP(E23,hoja!$A$2:$E$970,5,FALSE),0) -> MEDELLÍN | H23: =IFERROR(VLOOKUP(E23,hoja!A:C,3,FALSE),0) -> 0079 | I23: =D23&H23 -> 81010079 | J23: 23.35 | K23: 569.3575 | L23: =IF(B23=F23,"REGIONAL","NACIONAL") -> NACIONAL | M23: Principal | N23: {=IFERROR(IF(M23="Principal","LES_ACTIVE",LES_INACTIVE),0)} -> LES_ACTIVE | O23: =IF(K23<=250,25,IF(K23<=500,16,IF(K23<=800,12,IF(K23<=1100,8,IF(K23<=1400,6,IF(K23<=1700,5)))))) -> 12 | P23: =D23&H23&M23 -> 81010079Principal
A24: AIR LIQUIDE SIBATE | B24: =IFERROR(VLOOKUP(A24,hoja!$A$2:$E$970,4,FALSE),0) -> CENTRO | C24: =IFERROR(VLOOKUP(A24,hoja!$A$2:$E$1370,5,FALSE),0) -> BOGOTÁ | D24: =IFERROR(VLOOKUP(A24,hoja!A:D,3,FALSE),0) -> 8101 | E24: POSTOBON MALAMBO | F24: =IFERROR(VLOOKUP(E24,hoja!$A$2:$E$970,4,FALSE),0) -> COSTA | G24: =IFERROR(VLOOKUP(E24,hoja!$A$2:$E$970,5,FALSE),0) -> BARRANQUILLA | H24: =IFERROR(VLOOKUP(E24,hoja!A:C,3,FALSE),0) -> 0111 | I24: =D24&H24 -> 81010111 | J24: =+K24/16.8 -> 56.190476 | K24: 944 | L24: =IF(B24=F24,"REGIONAL","NACIONAL") -> NACIONAL | M24: Piedecuesta | N24: LES_INACTIVE | O24: =IF(K24<=250,25,IF(K24<=500,16,IF(K24<=800,12,IF(K24<=1100,8,IF(K24<=1400,6,IF(K24<=1700,5)))))) -> 8 | P24: =D24&H24&M24 -> 81010111Piedecuesta
A25: AIR LIQUIDE SIBATE | B25: =IFERROR(VLOOKUP(A25,hoja!$A$2:$E$970,4,FALSE),0) -> CENTRO | C25: =IFERROR(VLOOKUP(A25,hoja!$A$2:$E$1370,5,FALSE),0) -> BOGOTÁ | D25: =IFERROR(VLOOKUP(A25,hoja!A:D,3,FALSE),0) -> 8101 | E25: POSTOBON MALAMBO | F25: =IFERROR(VLOOKUP(E25,hoja!$A$2:$E$970,4,FALSE),0) -> COSTA | G25: =IFERROR(VLOOKUP(E25,hoja!$A$2:$E$970,5,FALSE),0) -> BARRANQUILLA | H25: =IFERROR(VLOOKUP(E25,hoja!A:C,3,FALSE),0) -> 0111 | I25: =D25&H25 -> 81010111 | J25: =+K25/16.8 -> 62.202381 | K25: 1045 | L25: =IF(B25=F25,"REGIONAL","NACIONAL") -> NACIONAL | M25: La vega | N25: LES_INACTIVE | O25: =IF(K25<=250,25,IF(K25<=500,16,IF(K25<=800,12,IF(K25<=1100,8,IF(K25<=1400,6,IF(K25<=1700,5)))))) -> 8 | P25: =D25&H25&M25 -> 81010111La vega
A26: AIR LIQUIDE SIBATE | B26: =IFERROR(VLOOKUP(A26,hoja!$A$2:$E$970,4,FALSE),0) -> CENTRO | C26: =IFERROR(VLOOKUP(A26,hoja!$A$2:$E$1370,5,FALSE),0) -> BOGOTÁ | D26: =IFERROR(VLOOKUP(A26,hoja!A:D,3,FALSE),0) -> 8101 | E26: POSTOBON MALAMBO | F26: =IFERROR(VLOOKUP(E26,hoja!$A$2:$E$970,4,FALSE),0) -> COSTA | G26: =IFERROR(VLOOKUP(E26,hoja!$A$2:$E$970,5,FALSE),0) -> BARRANQUILLA | H26: =IFERROR(VLOOKUP(E26,hoja!A:C,3,FALSE),0) -> 0111 | I26: =D26&H26 -> 81010111 | J26: =+K26/16.8 -> 65.4825 | K26: 1100.106 | L26: =IF(B26=F26,"REGIONAL","NACIONAL") -> NACIONAL | M26: Principal | N26: {=IFERROR(IF(M26="Principal","LES_ACTIVE",LES_INACTIVE),0)} -> LES_ACTIVE | O26: =IF(K26<=250,25,IF(K26<=500,16,IF(K26<=800,12,IF(K26<=1100,8,IF(K26<=1400,6,IF(K26<=1700,5)))))) -> 6 | P26: =D26&H26&M26 -> 81010111Principal
A27: AIR LIQUIDE SIBATE | B27: =IFERROR(VLOOKUP(A27,hoja!$A$2:$E$970,4,FALSE),0) -> CENTRO | C27: =IFERROR(VLOOKUP(A27,hoja!$A$2:$E$1370,5,FALSE),0) -> BOGOTÁ | D27: =IFERROR(VLOOKUP(A27,hoja!A:D,3,FALSE),0) -> 8101 | E27: POSTOBON PEREIRA | F27: =IFERROR(VLOOKUP(E27,hoja!$A$2:$E$970,4,FALSE),0) -> OCCIDENTE | G27: =IFERROR(VLOOKUP(E27,hoja!$A$2:$E$970,5,FALSE),0) -> PEREIRA | H27: =IFERROR(VLOOKUP(E27,hoja!A:C,3,FALSE),0) -> 0198 | I27: =D27&H27 -> 81010198 | J27: 20.450571 | K27: 355 | L27: =IF(B27=F27,"REGIONAL","NACIONAL") -> NACIONAL | M27: Principal | N27: {=IFERROR(IF(M27="Principal","LES_ACTIVE",LES_INACTIVE),0)} -> LES_ACTIVE | O27: =IF(K27<=250,25,IF(K27<=500,16,IF(K27<=800,12,IF(K27<=1100,8,IF(K27<=1400,6,IF(K27<=1700,5)))))) -> 16 | P27: =D27&H27&M27 -> 81010198Principal
A28: AIR LIQUIDE SIBATE | B28: =IFERROR(VLOOKUP(A28,hoja!$A$2:$E$970,4,FALSE),0) -> CENTRO | C28: =IFERROR(VLOOKUP(A28,hoja!$A$2:$E$1370,5,FALSE),0) -> BOGOTÁ | D28: =IFERROR(VLOOKUP(A28,hoja!A:D,3,FALSE),0) -> 8101 | E28: POSTOBON YUMBO | F28: =IFERROR(VLOOKUP(E28,hoja!$A$2:$E$970,4,FALSE),0) -> OCCIDENTE | G28: =IFERROR(VLOOKUP(E28,hoja!$A$2:$E$970,5,FALSE),0) -> CALI | H28: =IFERROR(VLOOKUP(E28,hoja!A:C,3,FALSE),0) -> 0410 | I28: =D28&H28 -> 81010410 | J28: 24 | K28: 485.77 | L28: =IF(B28=F28,"REGIONAL","NACIONAL") -> NACIONAL | M28: Principal | N28: {=IFERROR(IF(M28="Principal","LES_ACTIVE",LES_INACTIVE),0)} -> LES_ACTIVE | O28: =IF(K28<=250,25,IF(K28<=500,16,IF(K28<=800,12,IF(K28<=1100,8,IF(K28<=1400,6,IF(K28<=1700,5)))))) -> 16 | P28: =D28&H28&M28 -> 81010410Principal
A29: AIR LIQUIDE SIBATE | B29: =IFERROR(VLOOKUP(A29,hoja!$A$2:$E$970,4,FALSE),0) -> CENTRO | C29: =IFERROR(VLOOKUP(A29,hoja!$A$2:$E$1370,5,FALSE),0) -> BOGOTÁ | D29: =IFERROR(VLOOKUP(A29,hoja!A:D,3,FALSE),0) -> 8101 | E29: RECREO | F29: =IFERROR(VLOOKUP(E29,hoja!$A$2:$E$970,4,FALSE),0) -> CENTRO | G29: =IFERROR(VLOOKUP(E29,hoja!$A$2:$E$970,5,FALSE),0) -> ZIPAQUIRÁ | H29: =IFERROR(VLOOKUP(E29,hoja!A:C,3,FALSE),0) -> 3039 | I29: =D29&H29 -> 81013039 | J29: 0.40857143 | K29: 14.3 | L29: =IF(B29=F29,"REGIONAL","NACIONAL") -> REGIONAL | M29: Principal | N29: {=IFERROR(IF(M29="Principal","LES_ACTIVE",LES_INACTIVE),0)} -> LES_ACTIVE | O29: =IF(K29<=250,25,IF(K29<=500,16,IF(K29<=800,12,IF(K29<=1100,8,IF(K29<=1400,6,IF(K29<=1700,5)))))) -> 25 | P29: =D29&H29&M29 -> 81013039Principal
A30: AIR LIQUIDE SIBATE | B30: =IFERROR(VLOOKUP(A30,hoja!$A$2:$E$970,4,FALSE),0) -> CENTRO | C30: =IFERROR(VLOOKUP(A30,hoja!$A$2:$E$1370,5,FALSE),0) -> BOGOTÁ | D30: =IFERROR(VLOOKUP(A30,hoja!A:D,3,FALSE),0) -> 8101 | E30: TOCANCIPÁ | F30: =IFERROR(VLOOKUP(E30,hoja!$A$2:$E$970,4,FALSE),0) -> CENTRO | G30: =IFERROR(VLOOKUP(E30,hoja!$A$2:$E$970,5,FALSE),0) -> TOCANCIPÁ | H30: =IFERROR(VLOOKUP(E30,hoja!A:C,3,FALSE),0) -> 2058 | I30: =D30&H30 -> 81012058 | K30: 13.8 | L30: =IF(B30=F30,"REGIONAL","NACIONAL") -> REGIONAL | M30: Principal | N30: {=IFERROR(IF(M30="Principal","LES_ACTIVE",LES_INACTIVE),0)} -> LES_ACTIVE | O30: =IF(K30<=250,25,IF(K30<=500,16,IF(K30<=800,12,IF(K30<=1100,8,IF(K30<=1400,6,IF(K30<=1700,5)))))) -> 25 | P30: =D30&H30&M30 -> 81012058Principal
A31: AIR LIQUIDE SIBATE | B31: =IFERROR(VLOOKUP(A31,hoja!$A$2:$E$970,4,FALSE),0) -> CENTRO | C31: =IFERROR(VLOOKUP(A31,hoja!$A$2:$E$1370,5,FALSE),0) -> BOGOTÁ | D31: =IFERROR(VLOOKUP(A31,hoja!A:D,3,FALSE),0) -> 8101 | E31: VEOLIA | F31: =IFERROR(VLOOKUP(E31,hoja!$A$2:$E$970,4,FALSE),0) -> CENTRO | G31: =IFERROR(VLOOKUP(E31,hoja!$A$2:$E$970,5,FALSE),0) -> BOGOTÁ | H31: =IFERROR(VLOOKUP(E31,hoja!A:C,3,FALSE),0) -> 10228 | I31: =D31&H31 -> 810110228 | J31: 1.1942857 | K31: 41.8 | L31: =IF(B31=F31,"REGIONAL","NACIONAL") -> REGIONAL | M31: Principal | N31: {=IFERROR(IF(M31="Principal","LES_ACTIVE",LES_INACTIVE),0)} -> LES_ACTIVE | O31: =IF(K31<=250,25,IF(K31<=500,16,IF(K31<=800,12,IF(K31<=1100,8,IF(K31<=1400,6,IF(K31<=1700,5)))))) -> 25 | P31: =D31&H31&M31 -> 810110228Principal
A32: AMAGA | B32: =IFERROR(VLOOKUP(A32,hoja!$A$2:$E$970,4,FALSE),0) -> ANTIOQUIA | C32: =IFERROR(VLOOKUP(A32,hoja!$A$2:$E$1370,5,FALSE),0) -> MEDELLÍN | D32: =IFERROR(VLOOKUP(A32,hoja!A:D,3,FALSE),0) -> 60127 | E32: CALOTO-NGB | F32: =IFERROR(VLOOKUP(E32,hoja!$A$2:$E$970,4,FALSE),0) -> OCCIDENTE | G32: =IFERROR(VLOOKUP(E32,hoja!$A$2:$E$970,5,FALSE),0) -> CALOTO | H32: =IFERROR(VLOOKUP(E32,hoja!A:C,3,FALSE),0) -> 0445 | I32: =D32&H32 -> 601270445 | J32: 21.142857 | K32: 444 | L32: =IF(B32=F32,"REGIONAL","NACIONAL") -> NACIONAL | M32: Principal | N32: {=IFERROR(IF(M32="Principal","LES_ACTIVE",LES_INACTIVE),0)} -> LES_ACTIVE | O32: =IF(K32<=250,25,IF(K32<=500,16,IF(K32<=800,12,IF(K32<=1100,8,IF(K32<=1400,6,IF(K32<=1700,5)))))) -> 16 | P32: =D32&H32&M32 -> 601270445Principal
A33: AMAGA | B33: =IFERROR(VLOOKUP(A33,hoja!$A$2:$E$970,4,FALSE),0) -> ANTIOQUIA | C33: =IFERROR(VLOOKUP(A33,hoja!$A$2:$E$1370,5,FALSE),0) -> MEDELLÍN | D33: =IFERROR(VLOOKUP(A33,hoja!A:D,3,FALSE),0) -> 60127 | E33: INGENIO RISARALDA | F33: =IFERROR(VLOOKUP(E33,hoja!$A$2:$E$970,4,FALSE),0) -> OCCIDENTE | G33: =IFERROR(VLOOKUP(E33,hoja!$A$2:$E$970,5,FALSE),0) -> LA VIRGINIA | H33: =IFERROR(VLOOKUP(E33,hoja!A:C,3,FALSE),0) -> 60057 | I33: =D33&H33 -> 6012760057 | J33: 5.6 | K33: 196 | L33: =IF(B33=F33,"REGIONAL","NACIONAL") -> NACIONAL | M33: Principal | N33: {=IFERROR(IF(M33="Principal","LES_ACTIVE",LES_INACTIVE),0)} -> LES_ACTIVE | O33: =IF(K33<=250,25,IF(K33<=500,16,IF(K33<=800,12,IF(K33<=1100,8,IF(K33<=1400,6,IF(K33<=1700,5)))))) -> 25 | P33: =D33&H33&M33 -> 6012760057Principal
A34: AMCOR | B34: =IFERROR(VLOOKUP(A34,hoja!$A$2:$E$970,4,FALSE),0) -> OCCIDENTE | C34: =IFERROR(VLOOKUP(A34,hoja!$A$2:$E$1370,5,FALSE),0) -> CALI | D34: =IFERROR(VLOOKUP(A34,hoja!A:D,3,FALSE),0) -> 60109 | E34: CALI | F34: =IFERROR(VLOOKUP(E34,hoja!$A$2:$E$970,4,FALSE),0) -> OCCIDENTE | G34: =IFERROR(VLOOKUP(E34,hoja!$A$2:$E$970,5,FALSE),0) -> CALI | H34: =IFERROR(VLOOKUP(E34,hoja!A:C,3,FALSE),0) -> 3024 | I34: =D34&H34 -> 601093024 | K34: 8.1 | L34: =IF(B34=F34,"REGIONAL","NACIONAL") -> REGIONAL | M34: Principal | N34: {=IFERROR(IF(M34="Principal","LES_ACTIVE",LES_INACTIVE),0)} -> LES_ACTIVE | O34: =IF(K34<=250,25,IF(K34<=500,16,IF(K34<=800,12,IF(K34<=1100,8,IF(K34<=1400,6,IF(K34<=1700,5)))))) -> 25 | P34: =D34&H34&M34 -> 601093024Principal
A35: AMCOR | B35: =IFERROR(VLOOKUP(A35,hoja!$A$2:$E$970,4,FALSE),0) -> OCCIDENTE | C35: =IFERROR(VLOOKUP(A35,hoja!$A$2:$E$1370,5,FALSE),0) -> CALI | D35: =IFERROR(VLOOKUP(A35,hoja!A:D,3,FALSE),0) -> 60109 | E35: CALOTO-NGB | F35: =IFERROR(VLOOKUP(E35,hoja!$A$2:$E$970,4,FALSE),0) -> OCCIDENTE | G35: =IFERROR(VLOOKUP(E35,hoja!$A$2:$E$970,5,FALSE),0) -> CALOTO | H35: =IFERROR(VLOOKUP(E35,hoja!A:C,3,FALSE),0) -> 0445 | I35: =D35&H35 -> 601090445 | K35: 87.1 | L35: =IF(B35=F35,"REGIONAL","NACIONAL") -> REGIONAL | M35: Principal | N35: {=IFERROR(IF(M35="Principal","LES_ACTIVE",LES_INACTIVE),0)} -> LES_ACTIVE | O35: =IF(K35<=250,25,IF(K35<=500,16,IF(K35<=800,12,IF(K35<=1100,8,IF(K35<=1400,6,IF(K35<=1700,5)))))) -> 25 | P35: =D35&H35&M35 -> 601090445Principal
A36: AMCOR | B36: =IFERROR(VLOOKUP(A36,hoja!$A$2:$E$970,4,FALSE),0) -> OCCIDENTE | C36: =IFERROR(VLOOKUP(A36,hoja!$A$2:$E$1370,5,FALSE),0) -> CALI | D36: =IFERROR(VLOOKUP(A36,hoja!A:D,3,FALSE),0) -> 60109 | E36: PLANTA IBERPLAST | F36: =IFERROR(VLOOKUP(E36,hoja!$A$2:$E$970,4,FALSE),0) -> CENTRO | G36: =IFERROR(VLOOKUP(E36,hoja!$A$2:$E$970,5,FALSE),0) -> MADRID | H36: =IFERROR(VLOOKUP(E36,hoja!A:C,3,FALSE),0) -> 2023 | I36: =D36&H36 -> 601092023 | K36: 440 | L36: =IF(B36=F36,"REGIONAL","NACIONAL") -> NACIONAL | M36: Principal | N36: {=IFERROR(IF(M36="Principal","LES_ACTIVE",LES_INACTIVE),0)} -> LES_ACTIVE | O36: =IF(K36<=250,25,IF(K36<=500,16,IF(K36<=800,12,IF(K36<=1100,8,IF(K36<=1400,6,IF(K36<=1700,5)))))) -> 16 | P36: =D36&H36&M36 -> 601092023Principal
A37: AMCOR | B37: =IFERROR(VLOOKUP(A37,hoja!$A$2:$E$970,4,FALSE),0) -> OCCIDENTE | C37: =IFERROR(VLOOKUP(A37,hoja!$A$2:$E$1370,5,FALSE),0) -> CALI | D37: =IFERROR(VLOOKUP(A37,hoja!A:D,3,FALSE),0) -> 60109 | E37: POSTOBON BELLO | F37: =IFERROR(VLOOKUP(E37,hoja!$A$2:$E$970,4,FALSE),0) -> ANTIOQUIA | G37: =IFERROR(VLOOKUP(E37,hoja!$A$2:$E$970,5,FALSE),0) -> MEDELLÍN | H37: =IFERROR(VLOOKUP(E37,hoja!A:C,3,FALSE),0) -> 0079 | I37: =D37&H37 -> 601090079 | K37: 412 | L37: =IF(B37=F37,"REGIONAL","NACIONAL") -> NACIONAL | M37: Principal | N37: {=IFERROR(IF(M37="Principal","LES_ACTIVE",LES_INACTIVE),0)} -> LES_ACTIVE | O37: =IF(K37<=250,25,IF(K37<=500,16,IF(K37<=800,12,IF(K37<=1100,8,IF(K37<=1400,6,IF(K37<=1700,5)))))) -> 16 | P37: =D37&H37&M37 -> 601090079Principal
A38: AMCOR | B38: =IFERROR(VLOOKUP(A38,hoja!$A$2:$E$970,4,FALSE),0) -> OCCIDENTE | C38: =IFERROR(VLOOKUP(A38,hoja!$A$2:$E$1370,5,FALSE),0) -> CALI | D38: =IFERROR(VLOOKUP(A38,hoja!A:D,3,FALSE),0) -> 60109 | E38: POSTOBON MALAMBO | F38: =IFERROR(VLOOKUP(E38,hoja!$A$2:$E$970,4,FALSE),0) -> COSTA | G38: =IFERROR(VLOOKUP(E38,hoja!$A$2:$E$970,5,FALSE),0) -> BARRANQUILLA | H38: =IFERROR(VLOOKUP(E38,hoja!A:C,3,FALSE),0) -> 0111 | I38: =D38&H38 -> 601090111 | K38: 1086 | L38: =IF(B38=F38,"REGIONAL","NACIONAL") -> NACIONAL | M38: Principal | N38: {=IFERROR(IF(M38="Principal","LES_ACTIVE",LES_INACTIVE),0)} -> LES_ACTIVE | O38: =IF(K38<=250,25,IF(K38<=500,16,IF(K38<=800,12,IF(K38<=1100,8,IF(K38<=1400,6,IF(K38<=1700,5)))))) -> 8 | P38: =D38&H38&M38 -> 601090111Principal
A39: AMCOR | B39: =IFERROR(VLOOKUP(A39,hoja!$A$2:$E$970,4,FALSE),0) -> OCCIDENTE | C39: =IFERROR(VLOOKUP(A39,hoja!$A$2:$E$1370,5,FALSE),0) -> CALI | D39: =IFERROR(VLOOKUP(A39,hoja!A:D,3,FALSE),0) -> 60109 | E39: POSTOBON PEREIRA | F39: =IFERROR(VLOOKUP(E39,hoja!$A$2:$E$970,4,FALSE),0) -> OCCIDENTE | G39: =IFERROR(VLOOKUP(E39,hoja!$A$2:$E$970,5,FALSE),0) -> PEREIRA | H39: =IFERROR(VLOOKUP(E39,hoja!A:C,3,FALSE),0) -> 0198 | I39: =D39&H39 -> 601090198 | K39: 203 | L39: =IF(B39=F39,"REGIONAL","NACIONAL") -> REGIONAL | M39: Principal | N39: {=IFERROR(IF(M39="Principal","LES_ACTIVE",LES_INACTIVE),0)} -> LES_ACTIVE | O39: =IF(K39<=250,25,IF(K39<=500,16,IF(K39<=800,12,IF(K39<=1100,8,IF(K39<=1400,6,IF(K39<=1700,5)))))) -> 25 | P39: =D39&H39&M39 -> 601090198Principal
A40: AMCOR | B40: =IFERROR(VLOOKUP(A40,hoja!$A$2:$E$970,4,FALSE),0) -> OCCIDENTE | C40: =IFERROR(VLOOKUP(A40,hoja!$A$2:$E$1370,5,FALSE),0) -> CALI | D40: =IFERROR(VLOOKUP(A40,hoja!A:D,3,FALSE),0) -> 60109 | E40: POSTOBON YUMBO | F40: =IFERROR(VLOOKUP(E40,hoja!$A$2:$E$970,4,FALSE),0) -> OCCIDENTE | G40: =IFERROR(VLOOKUP(E40,hoja!$A$2:$E$970,5,FALSE),0) -> CALI | H40: =IFERROR(VLOOKUP(E40,hoja!A:C,3,FALSE),0) -> 0410 | I40: =D40&H40 -> 601090410 | K40: 4.5 | L40: =IF(B40=F40,"REGIONAL","NACIONAL") -> REGIONAL | M40: Principal | N40: {=IFERROR(IF(M40="Principal","LES_ACTIVE",LES_INACTIVE),0)} -> LES_ACTIVE | O40: =IF(K40<=250,25,IF(K40<=500,16,IF(K40<=800,12,IF(K40<=1100,8,IF(K40<=1400,6,IF(K40<=1700,5)))))) -> 25 | P40: =D40&H40&M40 -> 601090410Principal
...

Sheet hoja
A1: Plaza | B1: Nombre Centro | C1: Codigo SAP | D1: Regional | E1: Ciudad | F1: Ciudad SICETAC | G1: Equivalente SICETAC | H1: Código nómina | I1: Código facturación | J1: Ciudad Tablero RNDC | K1: COD CIUDAD SISETAC | L1: Ciudad Equivalente RNDC | M1: COD EQUIVALENTE SISETAC | N1: Plaza
A2: AIR LIQUIDE SIBATE | B2: AIR LIQUIDE SIBATE | C2: 8101 | D2: CENTRO | E2: BOGOTÁ | F2: SIBATE CUNDINAMARCA | G2: BOGOTA | I2: AIRLQSI | J2: =IFERROR(VLOOKUP(F2,'Ciudad tablero'!A:B,2,0),0) -> SIBATE CUNDINAMARCA | K2: =IFERROR(VLOOKUP(J2,'Ciudad tablero'!B:C,2,0),0) -> 25740000 | L2: =IFERROR(VLOOKUP(G2,'Ciudad tablero'!A:B,2,0),0) -> BOGOTA BOGOTA D. C. | M2: =IFERROR(VLOOKUP(L2,'Ciudad tablero'!B:C,2,0),0) -> 11001000 | N2: =+A2 -> AIR LIQUIDE SIBATE
A3: CALOTO-NGB | B3: CALOTO-NGB | C3: 0445 | D3: OCCIDENTE | E3: CALOTO | F3: CALOTO CAUCA | G3: CALI | I3: CALOT | J3: =IFERROR(VLOOKUP(F3,'Ciudad tablero'!A:B,2,0),0) -> CALOTO CAUCA | K3: =IFERROR(VLOOKUP(J3,'Ciudad tablero'!B:C,2,0),0) -> 19142000 | L3: =IFERROR(VLOOKUP(G3,'Ciudad tablero'!A:B,2,0),0) -> CALI VALLE DEL CAUCA | M3: =IFERROR(VLOOKUP(L3,'Ciudad tablero'!B:C,2,0),0) -> 76001000 | N3: =+A3 -> CALOTO-NGB
A4: CEDI AGUACHICA | B4: CEDI AGUACHICA | C4: 0437 | D4: SANTANDER | E4: AGUACHICA | F4: AGUACHICA CESAR | G4: BARRANCABERMEJA | I4: AGUAC | J4: =IFERROR(VLOOKUP(F4,'Ciudad tablero'!A:B,2,0),0) -> AGUACHICA CESAR | K4: =IFERROR(VLOOKUP(J4,'Ciudad tablero'!B:C,2,0),0) -> 20011000 | L4: =IFERROR(VLOOKUP(G4,'Ciudad tablero'!A:B,2,0),0) -> BARRANCABERMEJA SANTANDER | M4: =IFERROR(VLOOKUP(L4,'Ciudad tablero'!B:C,2,0),0) -> 68081000 | N4: =+A4 -> CEDI AGUACHICA
A5: CEDI ANSERMA | B5: CEDI ANSERMA | C5: 0146 | D5: OCCIDENTE | E5: ANSERMA | F5: ANSERMA CALDAS | G5: MANIZALES | I5: ANSER | J5: =IFERROR(VLOOKUP(F5,'Ciudad tablero'!A:B,2,0),0) -> 0 | K5: =IFERROR(VLOOKUP(J5,'Ciudad tablero'!B:C,2,0),0) -> 0 | L5: =IFERROR(VLOOKUP(G5,'Ciudad tablero'!A:B,2,0),0) -> MANIZALES CALDAS | M5: =IFERROR(VLOOKUP(L5,'Ciudad tablero'!B:C,2,0),0) -> 17001000 | N5: =+A5 -> CEDI ANSERMA
A6: CEDI ARACATACA | B6: CEDI ARACATACA | C6: 0119 | D6: COSTA | E6: ARACATACA | F6: ARACATACA MAGDALENA | G6: SANTA MARTA | I6: ARACA | J6: =IFERROR(VLOOKUP(F6,'Ciudad tablero'!A:B,2,0),0) -> ARACATACA MAGDALENA | K6: =IFERROR(VLOOKUP(J6,'Ciudad tablero'!B:C,2,0),0) -> 47053000 | L6: =IFERROR(VLOOKUP(G6,'Ciudad tablero'!A:B,2,0),0) -> SANTA MARTA MAGDALENA | M6: =IFERROR(VLOOKUP(L6,'Ciudad tablero'!B:C,2,0),0) -> 47001000 | N6: =+A6 -> CEDI ARACATACA
A7: CEDI ARMENIA | B7: CEDI ARMENIA | C7: 0142 | D7: OCCIDENTE | E7: ARMENIA | F7: ARMENIA | G7: PEREIRA | I7: ARMEN | J7: =IFERROR(VLOOKUP(F7,'Ciudad tablero'!A:B,2,0),0) -> ARMENIA QUINDIO | K7: =IFERROR(VLOOKUP(J7,'Ciudad tablero'!B:C,2,0),0) -> 63001000 | L7: =IFERROR(VLOOKUP(G7,'Ciudad tablero'!A:B,2,0),0) -> PEREIRA RISARALDA | M7: =IFERROR(VLOOKUP(L7,'Ciudad tablero'!B:C,2,0),0) -> 66001000 | N7: =+A7 -> CEDI ARMENIA
A8: CEDI BARBOSA | B8: CEDI BARBOSA | C8: 0446 | D8: SANTANDER | E8: BARBOSA | F8: BARBOSA SANTANDER | G8: DUITAMA | I8: BARBO | J8: =IFERROR(VLOOKUP(F8,'Ciudad tablero'!A:B,2,0),0) -> BARBOSA SANTANDER | K8: =IFERROR(VLOOKUP(J8,'Ciudad tablero'!B:C,2,0),0) -> 68077000 | L8: =IFERROR(VLOOKUP(G8,'Ciudad tablero'!A:B,2,0),0) -> DUITAMA BOYACA | M8: =IFERROR(VLOOKUP(L8,'Ciudad tablero'!B:C,2,0),0) -> 15238000 | N8: =+A8 -> CEDI BARBOSA
A9: CEDI BOSCONIA | B9: CEDI BOSCONIA | C9: 0449 | D9: COSTA | E9: BOSCONIA | F9: BOSCONIA CESAR | G9: SANTA MARTA | I9: BOSCO | J9: =IFERROR(VLOOKUP(F9,'Ciudad tablero'!A:B,2,0),0) -> BOSCONIA CESAR | K9: =IFERROR(VLOOKUP(J9,'Ciudad tablero'!B:C,2,0),0) -> 20060000 | L9: =IFERROR(VLOOKUP(G9,'Ciudad tablero'!A:B,2,0),0) -> SANTA MARTA MAGDALENA | M9: =IFERROR(VLOOKUP(L9,'Ciudad tablero'!B:C,2,0),0) -> 47001000 | N9: =+A9 -> CEDI BOSCONIA
A10: CEDI BUENAVENTURA | B10: CEDI BUENAVENTURA | C10: 0131 | D10: OCCIDENTE | E10: BUENAVENTURA | F10: BUENAVENTURA | G10: BUENAVENTURA | I10: BTURA | J10: =IFERROR(VLOOKUP(F10,'Ciudad tablero'!A:B,2,0),0) -> BUENAVENTURA VALLE DEL CAUCA | K10: =IFERROR(VLOOKUP(J10,'Ciudad tablero'!B:C,2,0),0) -> 76109000 | L10: =IFERROR(VLOOKUP(G10,'Ciudad tablero'!A:B,2,0),0) -> BUENAVENTURA VALLE DEL CAUCA | M10: =IFERROR(VLOOKUP(L10,'Ciudad tablero'!B:C,2,0),0) -> 76109000 | N10: =+A10 -> CEDI BUENAVENTURA
A11: CEDI BUGA | B11: CEDI BUGA | C11: 0411 | D11: OCCIDENTE | E11: BUGA | F11: GUADALAJARA DE BUGA VALLE DEL CAUCA | G11: CALI | I11: BUGA | J11: =IFERROR(VLOOKUP(F11,'Ciudad tablero'!A:B,2,0),0) -> GUADALAJARA DE BUGA VALLE DEL CAUCA | K11: =IFERROR(VLOOKUP(J11,'Ciudad tablero'!B:C,2,0),0) -> 76111000 | L11: =IFERROR(VLOOKUP(G11,'Ciudad tablero'!A:B,2,0),0) -> CALI VALLE DEL CAUCA | M11: =IFERROR(VLOOKUP(L11,'Ciudad tablero'!B:C,2,0),0) -> 76001000 | N11: =+A11 -> CEDI BUGA
A12: CEDI CALLE 80 | B12: CEDI CALLE 80 | C12: 0035 | D12: CENTRO | E12: BOGOTÁ | F12: TENJO CUNDINAMARCA | G12: BOGOTA | I12: CALLE | J12: =IFERROR(VLOOKUP(F12,'Ciudad tablero'!A:B,2,0),0) -> TENJO CUNDINAMARCA | K12: =IFERROR(VLOOKUP(J12,'Ciudad tablero'!B:C,2,0),0) -> 25799000 | L12: =IFERROR(VLOOKUP(G12,'Ciudad tablero'!A:B,2,0),0) -> BOGOTA BOGOTA D. C. | M12: =IFERROR(VLOOKUP(L12,'Ciudad tablero'!B:C,2,0),0) -> 11001000 | N12: =+A12 -> CEDI CALLE 80
A13: CEDI CAQUEZA | B13: CEDI CAQUEZA | C13: 0012 | D13: CENTRO | E13: CAQUEZA | F13: CAQUEZA CUNDINAMARCA | G13: BOGOTA | I13: CAQUEA | J13: =IFERROR(VLOOKUP(F13,'Ciudad tablero'!A:B,2,0),0) -> CAQUEZA CUNDINAMARCA | K13: =IFERROR(VLOOKUP(J13,'Ciudad tablero'!B:C,2,0),0) -> 25151000 | L13: =IFERROR(VLOOKUP(G13,'Ciudad tablero'!A:B,2,0),0) -> BOGOTA BOGOTA D. C. | M13: =IFERROR(VLOOKUP(L13,'Ciudad tablero'!B:C,2,0),0) -> 11001000 | N13: =+A13 -> CEDI CAQUEZA
... A84: PUERTO BUENAVENTURA | B84: PUERTO BUENAVENTURA | C84: 3001 | D84: OCCIDENTE | E84: BUENAVENTURA | F84: BUENAVENTURA | G84: BUENAVENTURA | I84: PBTURA | J84: =IFERROR(VLOOKUP(F84,'Ciudad tablero'!A:B,2,0),0) -> BUENAVENTURA VALLE DEL CAUCA | K84: =IFERROR(VLOOKUP(J84,'Ciudad tablero'!B:C,2,0),0) -> 76109000 | L84: =IFERROR(VLOOKUP(G84,'Ciudad tablero'!A:B,2,0),0) -> BUENAVENTURA VALLE DEL CAUCA | M84: =IFERROR(VLOOKUP(L84,'Ciudad tablero'!B:C,2,0),0) -> 76109000 | N84: =+A84 -> PUERTO BUENAVENTURA
A85: PUERTO CONTECAR CARTAGENA | B85: PUERTO CONTECAR CARTAGENA | C85: 3002 | D85: COSTA | E85: CARTAGENA | F85: CARTAGENA | G85: CARTAGENA | I85: PCONTE | J85: =IFERROR(VLOOKUP(F85,'Ciudad tablero'!A:B,2,0),0) -> CARTAGENA BOLIVAR | K85: =IFERROR(VLOOKUP(J85,'Ciudad tablero'!B:C,2,0),0) -> 13001000 | L85: =IFERROR(VLOOKUP(G85,'Ciudad tablero'!A:B,2,0),0) -> CARTAGENA BOLIVAR | M85: =IFERROR(VLOOKUP(L85,'Ciudad tablero'!B:C,2,0),0) -> 13001000 | N85: =+A85 -> PUERTO CONTECAR CARTAGENA
A86: PUERTO DE BARRANQUILLA | B86: PUERTO DE BARRANQUILLA | C86: 3000 | D86: COSTA | E86: BARRANQUILLA | F86: BARRANQUILLA | G86: BARRANQUILLA | I86: PBQLLA | J86: =IFERROR(VLOOKUP(F86,'Ciudad tablero'!A:B,2,0),0) -> BARRANQUILLA ATLANTICO | K86: =IFERROR(VLOOKUP(J86,'Ciudad tablero'!B:C,2,0),0) -> 8001000 | L86: =IFERROR(VLOOKUP(G86,'Ciudad tablero'!A:B,2,0),0) -> BARRANQUILLA ATLANTICO | M86: =IFERROR(VLOOKUP(L86,'Ciudad tablero'!B:C,2,0),0) -> 8001000 | N86: =+A86 -> PUERTO DE BARRANQUILLA
A87: PUNTO DE INTERCAMBIO BUGA | B87: PUNTO DE INTERCAMBIO BUGA | C87: 60062 | D87: OCCIDENTE | E87: BUGA | F87: GUADALAJARA DE BUGA VALLE DEL CAUCA | G87: CALI | I87: PBUGA | J87: =IFERROR(VLOOKUP(F87,'Ciudad tablero'!A:B,2,0),0) -> GUADALAJARA DE BUGA VALLE DEL CAUCA | K87: =IFERROR(VLOOKUP(J87,'Ciudad tablero'!B:C,2,0),0) -> 76111000 | L87: =IFERROR(VLOOKUP(G87,'Ciudad tablero'!A:B,2,0),0) -> CALI VALLE DEL CAUCA | M87: =IFERROR(VLOOKUP(L87,'Ciudad tablero'!B:C,2,0),0) -> 76001000 | N87: =+A87 -> PUNTO DE INTERCAMBIO BUGA
A88: PUNTO DE INTERCAMBIO CARMEN DE BOLIVAR | B88: PUNTO DE INTERCAMBIO CARMEN DE BOLIVAR | C88: 60063 | D88: COSTA | E88: CARMEN DE BOLIVA | F88: EL CARMEN DE BOLIVAR BOLIVAR | G88: SINCELEJO | I88: PCARM | J88: =IFERROR(VLOOKUP(F88,'Ciudad tablero'!A:B,2,0),0) -> EL CARMEN DE BOLIVAR BOLIVAR | K88: =IFERROR(VLOOKUP(J88,'Ciudad tablero'!B:C,2,0),0) -> 13244000 | L88: =IFERROR(VLOOKUP(G88,'Ciudad tablero'!A:B,2,0),0) -> SINCELEJO SUCRE | M88: =IFERROR(VLOOKUP(L88,'Ciudad tablero'!B:C,2,0),0) -> 70001000 | N88: =+A88 -> PUNTO DE INTERCAMBIO CARMEN DE BOLIVAR
A89: PUNTO DE INTERCAMBIO CARTAGO | B89: PUNTO DE INTERCAMBIO CARTAGO | C89: 60064 | D89: OCCIDENTE | E89: Pereira-Eficiente destino Yumb | F89: CARTAGO | G89: PEREIRA | I89: PCTAGO | J89: =IFERROR(VLOOKUP(F89,'Ciudad tablero'!A:B,2,0),0) -> CARTAGO VALLE DEL CAUCA | K89: =IFERROR(VLOOKUP(J89,'Ciudad tablero'!B:C,2,0),0) -> 76147000 | L89: =IFERROR(VLOOKUP(G89,'Ciudad tablero'!A:B,2,0),0) -> PEREIRA RISARALDA | M89: =IFERROR(VLOOKUP(L89,'Ciudad tablero'!B:C,2,0),0) -> 66001000 | N89: =+A89 -> PUNTO DE INTERCAMBIO CARTAGO
A90: PUNTO DE INTERCAMBIO CHACHAGUI | B90: PUNTO DE INTERCAMBIO CHACHAGUI | C90: 60065 | D90: OCCIDENTE | E90: CHACHAGUI | F90: PASTO | G90: PASTO | I90: PCHACH | J90: =IFERROR(VLOOKUP(F90,'Ciudad tablero'!A:B,2,0),0) -> PASTO NARINO | K90: =IFERROR(VLOOKUP(J90,'Ciudad tablero'!B:C,2,0),0) -> 52001000 | L90: =IFERROR(VLOOKUP(G90,'Ciudad tablero'!A:B,2,0),0) -> PASTO NARINO | M90: =IFERROR(VLOOKUP(L90,'Ciudad tablero'!B:C,2,0),0) -> 52001000 | N90: =+A90 -> PUNTO DE INTERCAMBIO CHACHAGUI
A91: PUNTO DE INTERCAMBIO CHINU | B91: PUNTO DE INTERCAMBIO CHINU | C91: 60066 | D91: OCCIDENTE | E91: CHINÚ | F91: CHINU | G91: SINCELEJO | I91: PCHINU | J91: =IFERROR(VLOOKUP(F91,'Ciudad tablero'!A:B,2,0),0) -> 0 | K91: =IFERROR(VLOOKUP(J91,'Ciudad tablero'!B:C,2,0),0) -> 0 | L91: =IFERROR(VLOOKUP(G91,'Ciudad tablero'!A:B,2,0),0) -> SINCELEJO SUCRE | M91: =IFERROR(VLOOKUP(L91,'Ciudad tablero'!B:C,2,0),0) -> 70001000 | N91: =+A91 -> PUNTO DE INTERCAMBIO CHINU
A92: PUNTO DE INTERCAMBIO DOSQUEBRADAS | B92: PUNTO DE INTERCAMBIO DOSQUEBRADAS | C92: 60067 | D92: OCCIDENTE | E92: PEREIRA | F92: DOSQUEBRADAS RISARALDA | G92: PEREIRA | I92: PDOSQU | J92: =IFERROR(VLOOKUP(F92,'Ciudad tablero'!A:B,2,0),0) -> DOSQUEBRADAS RISARALDA | K92: =IFERROR(VLOOKUP(J92,'Ciudad tablero'!B:C,2,0),0) -> 66170000 | L92: =IFERROR(VLOOKUP(G92,'Ciudad tablero'!A:B,2,0),0) -> PEREIRA RISARALDA | M92: =IFERROR(VLOOKUP(L92,'Ciudad tablero'!B:C,2,0),0) -> 66001000 | N92: =+A92 -> PUNTO DE INTERCAMBIO DOSQUEBRADAS
A93: PUNTO DE INTERCAMBIO EDS EL MOLINO PIEDECUESTA | B93: PUNTO DE INTERCAMBIO EDS EL MOLINO PIEDECUESTA | C93: 60068 | D93: SANTANDER | E93: PIEDECUESTA | F93: PIEDECUESTA SANTANDER | G93: BUCARAMANGA | I93: PMOLIN | J93: =IFERROR(VLOOKUP(F93,'Ciudad tablero'!A:B,2,0),0) -> PIEDECUESTA SANTANDER | K93: =IFERROR(VLOOKUP(J93,'Ciudad tablero'!B:C,2,0),0) -> 68547000 | L93: =IFERROR(VLOOKUP(G93,'Ciudad tablero'!A:B,2,0),0) -> BUCARAMANGA SANTANDER | M93: =IFERROR(VLOOKUP(L93,'Ciudad tablero'!B:C,2,0),0) -> 68001000 | N93: =+A93 -> PUNTO DE INTERCAMBIO EDS EL MOLINO PIEDECUESTA
A94: PUNTO DE INTERCAMBIO EDS LA MULERA CUCUTA | B94: PUNTO DE INTERCAMBIO EDS LA MULERA CUCUTA | C94: 60069 | D94: SANTANDER | E94: CÚCUTA | F94: CÚCUTA | G94: CUCUTA NORTE DE SANTANDER | I94: PCUCUT | J94: =IFERROR(VLOOKUP(F94,'Ciudad tablero'!A:B,2,0),0) -> CUCUTA NORTE DE SANTANDER | K94: =IFERROR(VLOOKUP(J94,'Ciudad tablero'!B:C,2,0),0) -> 54001000 | L94: =IFERROR(VLOOKUP(G94,'Ciudad tablero'!A:B,2,0),0) -> CÚCUTA | M94: =IFERROR(VLOOKUP(L94,'Ciudad tablero'!B:C,2,0),0) -> 54001000 | N94: =+A94 -> PUNTO DE INTERCAMBIO EDS LA MULERA CUCUTA
A95: PUNTO DE INTERCAMBIO EL DESCANSO PAMPLONA | B95: PUNTO DE INTERCAMBIO EL DESCANSO PAMPLONA | C95: 60070 | D95: SANTANDER | E95: PAMPLONITA | F95: PAMPLONA NORTE DE SANTANDER | G95: CÚCUTA | I95: PPAMPL | J95: =IFERROR(VLOOKUP(F95,'Ciudad tablero'!A:B,2,0),0) -> PAMPLONA NORTE DE SANTANDER | K95: =IFERROR(VLOOKUP(J95,'Ciudad tablero'!B:C,2,0),0) -> 54518000 | L95: =IFERROR(VLOOKUP(G95,'Ciudad tablero'!A:B,2,0),0) -> CUCUTA NORTE DE SANTANDER | M95: =IFERROR(VLOOKUP(L95,'Ciudad tablero'!B:C,2,0),0) -> 54001000 | N95: =+A95 -> PUNTO DE INTERCAMBIO EL DESCANSO PAMPLONA
A96: PUNTO DE INTERCAMBIO GUALANDAY | B96: PUNTO DE INTERCAMBIO GUALANDAY | C96: 3042 | D96: CENTRO | E96: GUALANDAY | F96: GUALANDAY COELLO TOLIMA | G96: IBAGUÉ | I96: PGUAND | J96: =IFERROR(VLOOKUP(F96,'Ciudad tablero'!A:B,2,0),0) -> GUALANDAY COELLO TOLIMA | K96: =IFERROR(VLOOKUP(J96,'Ciudad tablero'!B:C,2,0),0) -> 73200001 | L96: =IFERROR(VLOOKUP(G96,'Ciudad tablero'!A:B,2,0),0) -> IBAGUE TOLIMA | M96: =IFERROR(VLOOKUP(L96,'Ciudad tablero'!B:C,2,0),0) -> 73001000 | N96: =+A96 -> PUNTO DE INTERCAMBIO GUALANDAY
A97: PUNTO DE INTERCAMBIO LA FELISA | B97: PUNTO DE INTERCAMBIO LA FELISA | C97: 60071 | D97: OCCIDENTE | E97: LA FELISA | F97: LA PINTADA ANTIOQUIA | G97: RIOSUCIO CALDAS | I97: PFELISA | J97: =IFERROR(VLOOKUP(F97,'Ciudad tablero'!A:B,2,0),0) -> LA PINTADA ANTIOQUIA | K97: =IFERROR(VLOOKUP(J97,'Ciudad tablero'!B:C,2,0),0) -> 5390000 | L97: =IFERROR(VLOOKUP(G97,'Ciudad tablero'!A:B,2,0),0) -> RIOSUCIO CALDAS | M97: =IFERROR(VLOOKUP(L97,'Ciudad tablero'!B:C,2,0),0) -> 17614000 | N97: =+A97 -> PUNTO DE INTERCAMBIO LA FELISA
A98: PUNTO DE INTERCAMBIO LA LIZAMA BARRANCABERMEJA | B98: PUNTO DE INTERCAMBIO LA LIZAMA BARRANCABERMEJA | C98: 60072 | D98: SANTANDER | E98: LA LIZAMA | F98: BARRANCABERMEJA | G98: BUCARAMANGA | I98: PLIZAMA | J98: =IFERROR(VLOOKUP(F98,'Ciudad tablero'!A:B,2,0),0) -> BARRANCABERMEJA SANTANDER | K98: =IFERROR(VLOOKUP(J98,'Ciudad tablero'!B:C,2,0),0) -> 68081000 | L98: =IFERROR(VLOOKUP(G98,'Ciudad tablero'!A:B,2,0),0) -> BUCARAMANGA SANTANDER | M98: =IFERROR(VLOOKUP(L98,'Ciudad tablero'!B:C,2,0),0) -> 68001000 | N98: =+A98 -> PUNTO DE INTERCAMBIO LA LIZAMA BARRANCABERMEJA
A99: PUNTO DE INTERCAMBIO LA PINTADA | B99: PUNTO DE INTERCAMBIO LA PINTADA | C99: 60073 | D99: OCCIDENTE | E99: LA PINTADA | F99: LA PINTADA ANTIOQUIA | G99: MEDELLÍN | I99: PPINTAD | J99: =IFERROR(VLOOKUP(F99,'Ciudad tablero'!A:B,2,0),0) -> LA PINTADA ANTIOQUIA | K99: =IFERROR(VLOOKUP(J99,'Ciudad tablero'!B:C,2,0),0) -> 5390000 | L99: =IFERROR(VLOOKUP(G99,'Ciudad tablero'!A:B,2,0),0) -> MEDELLIN ANTIOQUIA | M99: =IFERROR(VLOOKUP(L99,'Ciudad tablero'!B:C,2,0),0) -> 5001000 | N99: =+A99 -> PUNTO DE INTERCAMBIO LA PINTADA
A100: PUNTO DE INTERCAMBIO LA YE SAHAGUN | B100: PUNTO DE INTERCAMBIO LA YE SAHAGUN | C100: 60074 | D100: COSTA | E100: SAHAGÚN | F100: SAHAGUN CORDOBA | G100: SINCELEJO | I100: PSAHAG | J100: =IFERROR(VLOOKUP(F100,'Ciudad tablero'!A:B,2,0),0) -> SAHAGUN CORDOBA | K100: =IFERROR(VLOOKUP(J100,'Ciudad tablero'!B:C,2,0),0) -> 23660000 | L100: =IFERROR(VLOOKUP(G100,'Ciudad tablero'!A:B,2,0),0) -> SINCELEJO SUCRE | M100: =IFERROR(VLOOKUP(L100,'Ciudad tablero'!B:C,2,0),0) -> 70001000 | N100: =+A100 -> PUNTO DE INTERCAMBIO LA YE SAHAGUN
A101: PUNTO DE INTERCAMBIO NGB | B101: PUNTO DE INTERCAMBIO NGB | C101: 60075 | D101: OCCIDENTE | E101: CALOTO | F101: CALOTO CAUCA | G101: CALI | I101: PCALOT | J101: =IFERROR(VLOOKUP(F101,'Ciudad tablero'!A:B,2,0),0) -> CALOTO CAUCA | K101: =IFERROR(VLOOKUP(J101,'Ciudad tablero'!B:C,2,0),0) -> 19142000 | L101: =IFERROR(VLOOKUP(G101,'Ciudad tablero'!A:B,2,0),0) -> CALI VALLE DEL CAUCA | M101: =IFERROR(VLOOKUP(L101,'Ciudad tablero'!B:C,2,0),0) -> 76001000 | N101: =+A101 -> PUNTO DE INTERCAMBIO NGB
A102: PUNTO DE INTERCAMBIO PADUA | B102: PUNTO DE INTERCAMBIO PADUA | C102: 60076 | D102: CENTRO | E102: PADUA | F102: MARIQUITA TOLIMA | G102: IBAGUÉ | I102: PPADUA | J102: =IFERROR(VLOOKUP(F102,'Ciudad tablero'!A:B,2,0),0) -> MARIQUITA TOLIMA | K102: =IFERROR(VLOOKUP(J102,'Ciudad tablero'!B:C,2,0),0) -> 73443000 | L102: =IFERROR(VLOOKUP(G102,'Ciudad tablero'!A:B,2,0),0) -> IBAGUE TOLIMA | M102: =IFERROR(VLOOKUP(L102,'Ciudad tablero'!B:C,2,0),0) -> 73001000 | N102: =+A102 -> PUNTO DE INTERCAMBIO PADUA
A103: PUNTO DE INTERCAMBIO PIEDECUESTA | B103: PUNTO DE INTERCAMBIO PIEDECUESTA | C103: 60077 | D103: SANTANDER | E103: PIEDECUESTA | F103: PIEDECUESTA SANTANDER | G103: BUCARAMANGA | I103: PPCUES | J103: =IFERROR(VLOOKUP(F103,'Ciudad tablero'!A:B,2,0),0) -> PIEDECUESTA SANTANDER | K103: =IFERROR(VLOOKUP(J103,'Ciudad tablero'!B:C,2,0),0) -> 68547000 | L103: =IFERROR(VLOOKUP(G103,'Ciudad tablero'!A:B,2,0),0) -> BUCARAMANGA SANTANDER | M103: =IFERROR(VLOOKUP(L103,'Ciudad tablero'!B:C,2,0),0) -> 68001000 | N103: =+A103 -> PUNTO DE INTERCAMBIO PIEDECUESTA
A104: PUNTO DE INTERCAMBIO PUERTO LIBRE | B104: PUNTO DE INTERCAMBIO PUERTO LIBRE | C104: 10214 | D104: ANTIOQUIA | E104: PUERTO LIBRE | F104: PUERTO LIBRE | G104: LA DORADA | I104: PPLIBR | J104: =IFERROR(VLOOKUP(F104,'Ciudad tablero'!A:B,2,0),0) -> 0 | K104: =IFERROR(VLOOKUP(J104,'Ciudad tablero'!B:C,2,0),0) -> 0 | L104: =IFERROR(VLOOKUP(G104,'Ciudad tablero'!A:B,2,0),0) -> LA DORADA CALDAS | M104: =IFERROR(VLOOKUP(L104,'Ciudad tablero'!B:C,2,0),0) -> 17380000 | N104: =+A104 -> PUNTO DE INTERCAMBIO PUERTO LIBRE
A105: PUNTO DE INTERCAMBIO PUERTO TRIUNFO | B105: PUNTO DE INTERCAMBIO PUERTO TRIUNFO | C105: 60079 | D105: ANTIOQUIA | E105: PUERTO TRIUNFO | F105: PUERTO TRIUNFO ANTIOQUIA | G105: LA DORADA | I105: PPTRIU | J105: =IFERROR(VLOOKUP(F105,'Ciudad tablero'!A:B,2,0),0) -> PUERTO TRIUNFO ANTIOQUIA | K105: =IFERROR(VLOOKUP(J105,'Ciudad tablero'!B:C,2,0),0) -> 5591000 | L105: =IFERROR(VLOOKUP(G105,'Ciudad tablero'!A:B,2,0),0) -> LA DORADA CALDAS | M105: =IFERROR(VLOOKUP(L105,'Ciudad tablero'!B:C,2,0),0) -> 17380000 | N105: =+A105 -> PUNTO DE INTERCAMBIO PUERTO TRIUNFO
A106: PUNTO DE INTERCAMBIO RICAURTE | B106: PUNTO DE INTERCAMBIO RICAURTE | C106: 60080 | D106: CENTRO | E106: RICAURTE | F106: RICAURTE CUNDINAMARCA | G106: IBAGUÉ | I106: PRICAU | J106: =IFERROR(VLOOKUP(F106,'Ciudad tablero'!A:B,2,0),0) -> RICAURTE CUNDINAMARCA | K106: =IFERROR(VLOOKUP(J106,'Ciudad tablero'!B:C,2,0),0) -> 25612000 | L106: =IFERROR(VLOOKUP(G106,'Ciudad tablero'!A:B,2,0),0) -> IBAGUE TOLIMA | M106: =IFERROR(VLOOKUP(L106,'Ciudad tablero'!B:C,2,0),0) -> 73001000 | N106: =+A106 -> PUNTO DE INTERCAMBIO RICAURTE
A107: PUNTO DE INTERCAMBIO RIOSUCIO | B107: PUNTO DE INTERCAMBIO RIOSUCIO | C107: 60081 | D107: CENTRO | E107: RIOSUCIO | F107: RIOSUCIO CALDAS | G107: MANIZALES CALDAS | I107: PRIOSU | J107: =IFERROR(VLOOKUP(F107,'Ciudad tablero'!A:B,2,0),0) -> RIOSUCIO CALDAS | K107: =IFERROR(VLOOKUP(J107,'Ciudad tablero'!B:C,2,0),0) -> 17614000 | L107: =IFERROR(VLOOKUP(G107,'Ciudad tablero'!A:B,2,0),0) -> MANIZALES | M107: =IFERROR(VLOOKUP(L107,'Ciudad tablero'!B:C,2,0),0) -> 17001000 | N107: =+A107 -> PUNTO DE INTERCAMBIO RIOSUCIO
A108: PUNTO DE INTERCAMBIO SAMPUES | B108: PUNTO DE INTERCAMBIO SAMPUES | C108: 60082 | D108: COSTA | E108: SAMPUES | F108: SAMPUES SUCRE | G108: SINCELEJO | I108: PSAMPU | J108: =IFERROR(VLOOKUP(F108,'Ciudad tablero'!A:B,2,0),0) -> SAMPUES SUCRE | K108: =IFERROR(VLOOKUP(J108,'Ciudad tablero'!B:C,2,0),0) -> 70670000 | L108: =IFERROR(VLOOKUP(G108,'Ciudad tablero'!A:B,2,0),0) -> SINCELEJO SUCRE | M108: =IFERROR(VLOOKUP(L108,'Ciudad tablero'!B:C,2,0),0) -> 70001000 | N108: =+A108 -> PUNTO DE INTERCAMBIO SAMPUES
A109: PUNTO DE INTERCAMBIO SANTA MARTA | B109: PUNTO DE INTERCAMBIO SANTA MARTA | C109: 60083 | D109: COSTA | E109: SANTA MARTA | F109: SANTA MARTA | G109: SANTA MARTA | I109: PSTAMRT | J109: =IFERROR(VLOOKUP(F109,'Ciudad tablero'!A:B,2,0),0) -> SANTA MARTA MAGDALENA | K109: =IFERROR(VLOOKUP(J109,'Ciudad tablero'!B:C,2,0),0) -> 47001000 | L109: =IFERROR(VLOOKUP(G109,'Ciudad tablero'!A:B,2,0),0) -> SANTA MARTA MAGDALENA | M109: =IFERROR(VLOOKUP(L109,'Ciudad tablero'!B:C,2,0),0) -> 47001000 | N109: =+A109 -> PUNTO DE INTERCAMBIO SANTA MARTA
A110: PUNTO DE INTERCAMBIO SANTANA | B110: PUNTO DE INTERCAMBIO SANTANA | C110: 60084 | D110: SANTANDER | E110: SANTANA | F110: BARBOSA SANTANDER | G110: SAN GIL SANTANDER | I110: PSTANA | J110: =IFERROR(VLOOKUP(F110,'Ciudad tablero'!A:B,2,0),0) -> BARBOSA SANTANDER | K110: =IFERROR(VLOOKUP(J110,'Ciudad tablero'!B:C,2,0),0) -> 68077000 | L110: =IFERROR(VLOOKUP(G110,'Ciudad tablero'!A:B,2,0),0) -> SAN GIL SANTANDER | M110: =IFERROR(VLOOKUP(L110,'Ciudad tablero'!B:C,2,0),0) -> 68679000 | N110: =+A110 -> PUNTO DE INTERCAMBIO SANTANA
...

Sheet Maestro de rutas
A1: Origen | B1: Regional origen | C1: Codigo origen | D1: Destino | E1: Regional destino | F1: Codigo destino | G1: Mediana de Duración real | H1: Cantidad de viajes | I1: Mediana de TraveledDistance
A2: AIR LIQUIDE | B2: =VLOOKUP(A2,hoja!$A$1:$E$887,5,FALSE) -> #N/A | C2: =VLOOKUP(A2,hoja!A:D,3,FALSE) -> #N/A | D2: Bavaria Tocancipa | E2: =VLOOKUP(D2,hoja!$A$1:$E$161,5,FALSE) -> #N/A | F2: =VLOOKUP(D2,hoja!A:C,3,FALSE) -> 50189 | G2: 1.3702778 | H2: 3 | I2: 76140
A3: AIR LIQUIDE | B3: =VLOOKUP(A3,hoja!$A$1:$E$161,5,FALSE) -> #N/A | C3: =VLOOKUP(A3,hoja!A:D,3,FALSE) -> #N/A | D3: CENTRAL CERVECERA - SESQUILE | E3: =VLOOKUP(D3,hoja!$A$1:$E$161,5,FALSE) -> SESQUILÉ | F3: =VLOOKUP(D3,hoja!A:C,3,FALSE) -> 1501 | G3: 1.0288889 | H3: 8 | I3: 82938.5
A4: AIR LIQUIDE | B4: =VLOOKUP(A4,hoja!$A$1:$E$161,5,FALSE) -> #N/A | C4: =VLOOKUP(A4,hoja!A:D,3,FALSE) -> #N/A | D4: ENKA DE COLOMBIA | E4: =VLOOKUP(D4,hoja!$A$1:$E$161,5,FALSE) -> #N/A | F4: =VLOOKUP(D4,hoja!A:C,3,FALSE) -> 3038 | G4: 37.551389 | H4: 19 | I4: 525786
A5: AIR LIQUIDE | B5: =VLOOKUP(A5,hoja!$A$1:$E$161,5,FALSE) -> #N/A | C5: =VLOOKUP(A5,hoja!A:D,3,FALSE) -> #N/A | D5: GASCOL CENTRO | E5: =VLOOKUP(D5,hoja!$A$1:$E$161,5,FALSE) -> BOGOTÁ | F5: =VLOOKUP(D5,hoja!A:C,3,FALSE) -> 0002 | G5: 2.4833333 | H5: 1 | I5: 111299
A6: AIR LIQUIDE | B6: =VLOOKUP(A6,hoja!$A$1:$E$161,5,FALSE) -> #N/A | C6: =VLOOKUP(A6,hoja!A:D,3,FALSE) -> #N/A | D6: GASCOL SUR | E6: =VLOOKUP(D6,hoja!$A$1:$E$161,5,FALSE) -> BOGOTÁ | F6: =VLOOKUP(D6,hoja!A:C,3,FALSE) -> 0011 | G6: 12.566667 | H6: 24 | I6: 126898.5
A7: AIR LIQUIDE | B7: =VLOOKUP(A7,hoja!$A$1:$E$161,5,FALSE) -> #N/A | C7: =VLOOKUP(A7,hoja!A:D,3,FALSE) -> #N/A | D7: GASEOSAS LUX DUITAMA | E7: =VLOOKUP(D7,hoja!$A$1:$E$161,5,FALSE) -> DUITAMA | F7: =VLOOKUP(D7,hoja!A:C,3,FALSE) -> 0441 | G7: 11.153333 | H7: 12 | I7: 237665.5
A8: AIR LIQUIDE | B8: =VLOOKUP(A8,hoja!$A$1:$E$161,5,FALSE) -> #N/A | C8: =VLOOKUP(A8,hoja!A:D,3,FALSE) -> #N/A | D8: GASEOSAS LUX PIEDECUESTA | E8: =VLOOKUP(D8,hoja!$A$1:$E$161,5,FALSE) -> PIEDECUESTA | F8: =VLOOKUP(D8,hoja!A:C,3,FALSE) -> 0422 | G8: 30.816667 | H8: 22 | I8: 430588
A9: AIR LIQUIDE | B9: =VLOOKUP(A9,hoja!$A$1:$E$161,5,FALSE) -> #N/A | C9: =VLOOKUP(A9,hoja!A:D,3,FALSE) -> #N/A | D9: Metálicas Mendez | E9: =VLOOKUP(D9,hoja!$A$1:$E$161,5,FALSE) -> #N/A | F9: =VLOOKUP(D9,hoja!A:C,3,FALSE) -> 50250 | G9: 13.154722 | H9: 1 | I9: 147026
A10: AIR LIQUIDE | B10: =VLOOKUP(A10,hoja!$A$1:$E$161,5,FALSE) -> #N/A | C10: =VLOOKUP(A10,hoja!A:D,3,FALSE) -> #N/A | D10: Parqueadero el Tunal | E10: =VLOOKUP(D10,hoja!$A$1:$E$161,5,FALSE) -> #N/A | F10: =VLOOKUP(D10,hoja!A:C,3,FALSE) -> #N/A | G10: 1.5419444 | H10: 7 | I10: 127136
A11: AIR LIQUIDE | B11: =VLOOKUP(A11,hoja!$A$1:$E$161,5,FALSE) -> #N/A | C11: =VLOOKUP(A11,hoja!A:D,3,FALSE) -> #N/A | D11: PARQUEADERO TRANSCONTAINER | E11: =VLOOKUP(D11,hoja!$A$1:$E$161,5,FALSE) -> BOGOTÁ | F11: =VLOOKUP(D11,hoja!A:C,3,FALSE) -> 60002 | G11: 2.7166667 | H11: 3 | I11: 118779
A12: AIR LIQUIDE | B12: =VLOOKUP(A12,hoja!$A$1:$E$161,5,FALSE) -> #N/A | C12: =VLOOKUP(A12,hoja!A:D,3,FALSE) -> #N/A | D12: POSTOBON BELLO | E12: =VLOOKUP(D12,hoja!$A$1:$E$161,5,FALSE) -> MEDELLÍN | F12: =VLOOKUP(D12,hoja!A:C,3,FALSE) -> 0079 | G12: 28.15 | H12: 2 | I12: 569357.5
A13: AIR LIQUIDE | B13: =VLOOKUP(A13,hoja!$A$1:$E$161,5,FALSE) -> #N/A | C13: =VLOOKUP(A13,hoja!A:D,3,FALSE) -> #N/A | D13: POSTOBON MALAMBO | E13: =VLOOKUP(D13,hoja!$A$1:$E$161,5,FALSE) -> BARRANQUILLA | F13: =VLOOKUP(D13,hoja!A:C,3,FALSE) -> 0111 | G13: 62.525 | H13: 46 | I13: 1100106
A14: AIR LIQUIDE | B14: =VLOOKUP(A14,hoja!$A$1:$E$161,5,FALSE) -> #N/A | C14: =VLOOKUP(A14,hoja!A:D,3,FALSE) -> #N/A | D14: TALLER MANTENIMIENTO EDINSA CALLE 80 | E14: =VLOOKUP(D14,hoja!$A$1:$E$161,5,FALSE) -> BOGOTÁ | F14: =VLOOKUP(D14,hoja!A:C,3,FALSE) -> 60003 | G14: 1.5166667 | H14: 1 | I14: 363085
... A363: CEDI CHIQUINQUIRA | B363: =VLOOKUP(A363,hoja!$A$1:$E$161,5,FALSE) -> CHIQUINQUIRÁ | C363: =VLOOKUP(A363,hoja!A:D,3,FALSE) -> 0444 | D363: SURTIRETENES Y RODAMIENTOS LTDA | E363: =VLOOKUP(D363,hoja!$A$1:$E$161,5,FALSE) -> #N/A | F363: =VLOOKUP(D363,hoja!A:C,3,FALSE) -> #N/A | G363: 6.5666667 | H363: 1 | I363: 145862
A364: CEDI CHIQUINQUIRA | B364: =VLOOKUP(A364,hoja!$A$1:$E$161,5,FALSE) -> CHIQUINQUIRÁ | C364: =VLOOKUP(A364,hoja!A:D,3,FALSE) -> 0444 | D364: TALLER MANTENIMIENTO EDINSA BOGOTÁ | E364: =VLOOKUP(D364,hoja!$A$1:$E$161,5,FALSE) -> #N/A | F364: =VLOOKUP(D364,hoja!A:C,3,FALSE) -> #N/A | G364: 3.4833333 | H364: 1
A365: CEDI CHIQUINQUIRA | B365: =VLOOKUP(A365,hoja!$A$1:$E$161,5,FALSE) -> CHIQUINQUIRÁ | C365: =VLOOKUP(A365,hoja!A:D,3,FALSE) -> 0444 | D365: TALLER MANTENIMIENTO EDINSA CALLE 80 | E365: =VLOOKUP(D365,hoja!$A$1:$E$161,5,FALSE) -> BOGOTÁ | F365: =VLOOKUP(D365,hoja!A:C,3,FALSE) -> 60003 | G365: 4.9936111 | H365: 9 | I365: 135501
A366: CEDI FLORENCIA | B366: =VLOOKUP(A366,hoja!$A$1:$E$161,5,FALSE) -> FLORENCIA | C366: =VLOOKUP(A366,hoja!A:D,3,FALSE) -> 0388 | D366: CALOTO-NGB | E366: =VLOOKUP(D366,hoja!$A$1:$E$161,5,FALSE) -> CALOTO | F366: =VLOOKUP(D366,hoja!A:C,3,FALSE) -> 0445 | G366: 40.483333 | H366: 57 | I366: 739405
A367: CEDI FLORENCIA | B367: =VLOOKUP(A367,hoja!$A$1:$E$161,5,FALSE) -> FLORENCIA | C367: =VLOOKUP(A367,hoja!A:D,3,FALSE) -> 0388 | D367: CEDI CALLE 80 | E367: =VLOOKUP(D367,hoja!$A$1:$E$161,5,FALSE) -> BOGOTÁ | F367: =VLOOKUP(D367,hoja!A:C,3,FALSE) -> 0035 | G367: 35.716667 | H367: 3 | I367: 487149
A368: CEDI FLORENCIA | B368: =VLOOKUP(A368,hoja!$A$1:$E$161,5,FALSE) -> FLORENCIA | C368: =VLOOKUP(A368,hoja!A:D,3,FALSE) -> 0388 | D368: CENTRAL CERVECERA - SESQUILE | E368: =VLOOKUP(D368,hoja!$A$1:$E$161,5,FALSE) -> SESQUILÉ | F368: =VLOOKUP(D368,hoja!A:C,3,FALSE) -> 1501 | G368: 39.266667 | H368: 27 | I368: 615625
A369: CEDI FLORENCIA | B369: =VLOOKUP(A369,hoja!$A$1:$E$161,5,FALSE) -> FLORENCIA | C369: =VLOOKUP(A369,hoja!A:D,3,FALSE) -> 0388 | D369: GASCOL AGUAS | E369: =VLOOKUP(D369,hoja!$A$1:$E$161,5,FALSE) -> BOGOTÁ | F369: =VLOOKUP(D369,hoja!A:C,3,FALSE) -> 0002A | G369: 33.091667 | H369: 2 | I369: 578599
A370: CEDI FLORENCIA | B370: =VLOOKUP(A370,hoja!$A$1:$E$161,5,FALSE) -> FLORENCIA | C370: =VLOOKUP(A370,hoja!A:D,3,FALSE) -> 0388 | D370: GASCOL SUR | E370: =VLOOKUP(D370,hoja!$A$1:$E$161,5,FALSE) -> BOGOTÁ | F370: =VLOOKUP(D370,hoja!A:C,3,FALSE) -> 0011 | G370: 24.283333 | H370: 20 | I370: 537699.5
A371: CEDI FLORENCIA | B371: =VLOOKUP(A371,hoja!$A$1:$E$161,5,FALSE) -> FLORENCIA | C371: =VLOOKUP(A371,hoja!A:D,3,FALSE) -> 0388 | D371: GASEOSAS LUX BOGOTA | E371: =VLOOKUP(D371,hoja!$A$1:$E$161,5,FALSE) -> BOGOTÁ | F371: =VLOOKUP(D371,hoja!A:C,3,FALSE) -> 0021 | G371: 25.6 | H371: 146 | I371: 542981.5
A372: CEDI FLORENCIA | B372: =VLOOKUP(A372,hoja!$A$1:$E$161,5,FALSE) -> FLORENCIA | C372: =VLOOKUP(A372,hoja!A:D,3,FALSE) -> 0388 | D372: GASEOSAS LUX NEIVA | E372: =VLOOKUP(D372,hoja!$A$1:$E$161,5,FALSE) -> NEIVA | F372: =VLOOKUP(D372,hoja!A:C,3,FALSE) -> 0385 | G372: 6.6833333 | H372: 426 | I372: 234978
